/scratch/cnt0024/hmg2840/albert7a/anaconda3/lib/python3.7/site-packages/distributed/utils.py:136: RuntimeWarning: Couldn't detect a suitable IP address for reaching '8.8.8.8', defaulting to '127.0.0.1': [Errno 101] Network is unreachable
  RuntimeWarning,
distributed.nanny - INFO -         Start Nanny at: 'tcp://172.30.9.50:45785'
distributed.nanny - INFO -         Start Nanny at: 'tcp://172.30.9.50:39144'
distributed.nanny - INFO -         Start Nanny at: 'tcp://172.30.9.50:40945'
distributed.nanny - INFO -         Start Nanny at: 'tcp://172.30.9.50:39486'
distributed.nanny - INFO -         Start Nanny at: 'tcp://172.30.9.50:43550'
distributed.nanny - INFO -         Start Nanny at: 'tcp://172.30.9.50:41395'
distributed.nanny - INFO -         Start Nanny at: 'tcp://172.30.9.50:43572'
distributed.nanny - INFO -         Start Nanny at: 'tcp://172.30.9.50:33422'
distributed.nanny - INFO -         Start Nanny at: 'tcp://172.30.9.50:33311'
distributed.nanny - INFO -         Start Nanny at: 'tcp://172.30.9.50:36730'
distributed.nanny - INFO -         Start Nanny at: 'tcp://172.30.9.50:44492'
distributed.nanny - INFO -         Start Nanny at: 'tcp://172.30.9.50:40892'
distributed.nanny - INFO -         Start Nanny at: 'tcp://172.30.9.50:37632'
distributed.nanny - INFO -         Start Nanny at: 'tcp://172.30.9.50:41105'
distributed.nanny - INFO -         Start Nanny at: 'tcp://172.30.9.50:37702'
distributed.nanny - INFO -         Start Nanny at: 'tcp://172.30.9.50:45433'
distributed.nanny - INFO -         Start Nanny at: 'tcp://172.30.9.50:32963'
distributed.nanny - INFO -         Start Nanny at: 'tcp://172.30.9.50:37631'
distributed.nanny - INFO -         Start Nanny at: 'tcp://172.30.9.50:44987'
distributed.nanny - INFO -         Start Nanny at: 'tcp://172.30.9.50:43539'
distributed.nanny - INFO -         Start Nanny at: 'tcp://172.30.9.50:41275'
distributed.nanny - INFO -         Start Nanny at: 'tcp://172.30.9.50:45070'
distributed.nanny - INFO -         Start Nanny at: 'tcp://172.30.9.50:34098'
distributed.nanny - INFO -         Start Nanny at: 'tcp://172.30.9.50:33304'
distributed.nanny - INFO -         Start Nanny at: 'tcp://172.30.9.50:43299'
distributed.nanny - INFO -         Start Nanny at: 'tcp://172.30.9.50:39692'
distributed.nanny - INFO -         Start Nanny at: 'tcp://172.30.9.50:43271'
distributed.nanny - INFO -         Start Nanny at: 'tcp://172.30.9.50:44415'
distributed.nanny - INFO - Closing Nanny at 'tcp://172.30.9.50:45785'
distributed.nanny - INFO - Closing Nanny at 'tcp://172.30.9.50:39144'
distributed.nanny - INFO - Closing Nanny at 'tcp://172.30.9.50:40945'
distributed.nanny - INFO - Closing Nanny at 'tcp://172.30.9.50:39486'
distributed.nanny - INFO - Closing Nanny at 'tcp://172.30.9.50:43550'
distributed.nanny - INFO - Closing Nanny at 'tcp://172.30.9.50:41395'
distributed.nanny - INFO - Closing Nanny at 'tcp://172.30.9.50:43572'
distributed.nanny - INFO - Closing Nanny at 'tcp://172.30.9.50:33422'
distributed.nanny - INFO - Closing Nanny at 'tcp://172.30.9.50:33311'
distributed.nanny - INFO - Closing Nanny at 'tcp://172.30.9.50:36730'
distributed.nanny - INFO - Closing Nanny at 'tcp://172.30.9.50:44492'
distributed.nanny - INFO - Closing Nanny at 'tcp://172.30.9.50:40892'
distributed.nanny - INFO - Closing Nanny at 'tcp://172.30.9.50:37632'
distributed.nanny - INFO - Closing Nanny at 'tcp://172.30.9.50:41105'
distributed.nanny - INFO - Closing Nanny at 'tcp://172.30.9.50:37702'
distributed.nanny - INFO - Closing Nanny at 'tcp://172.30.9.50:45433'
distributed.nanny - INFO - Closing Nanny at 'tcp://172.30.9.50:32963'
distributed.nanny - INFO - Closing Nanny at 'tcp://172.30.9.50:37631'
distributed.nanny - INFO - Closing Nanny at 'tcp://172.30.9.50:44987'
distributed.nanny - INFO - Closing Nanny at 'tcp://172.30.9.50:43539'
distributed.nanny - INFO - Closing Nanny at 'tcp://172.30.9.50:41275'
distributed.nanny - INFO - Closing Nanny at 'tcp://172.30.9.50:45070'
distributed.nanny - INFO - Closing Nanny at 'tcp://172.30.9.50:34098'
distributed.nanny - INFO - Closing Nanny at 'tcp://172.30.9.50:33304'
distributed.nanny - INFO - Closing Nanny at 'tcp://172.30.9.50:43299'
distributed.nanny - INFO - Closing Nanny at 'tcp://172.30.9.50:39692'
distributed.nanny - INFO - Closing Nanny at 'tcp://172.30.9.50:43271'
distributed.nanny - INFO - Closing Nanny at 'tcp://172.30.9.50:44415'
distributed.nanny - WARNING - Worker process still alive after 47 seconds, killing
distributed.nanny - ERROR - Timed out connecting Nanny '<Nanny: None, threads: 1>' to scheduler 'tcp://172.30.100.4:42246'
Traceback (most recent call last):
  File "/scratch/cnt0024/hmg2840/albert7a/anaconda3/lib/python3.7/site-packages/distributed/nanny.py", line 303, in instantiate
    timedelta(seconds=self.death_timeout), self.process.start()
  File "/scratch/cnt0024/hmg2840/albert7a/anaconda3/lib/python3.7/site-packages/tornado/gen.py", line 729, in run
    value = future.result()
tornado.util.TimeoutError: Timeout
distributed.nanny - WARNING - Worker process 2275 was killed by signal 15
distributed.nanny - WARNING - Worker process still alive after 47 seconds, killing
distributed.nanny - WARNING - Worker process still alive after 47 seconds, killing
distributed.nanny - WARNING - Worker process still alive after 47 seconds, killing
distributed.nanny - ERROR - Timed out connecting Nanny '<Nanny: None, threads: 1>' to scheduler 'tcp://172.30.100.4:42246'
Traceback (most recent call last):
  File "/scratch/cnt0024/hmg2840/albert7a/anaconda3/lib/python3.7/site-packages/distributed/nanny.py", line 303, in instantiate
    timedelta(seconds=self.death_timeout), self.process.start()
  File "/scratch/cnt0024/hmg2840/albert7a/anaconda3/lib/python3.7/site-packages/tornado/gen.py", line 729, in run
    value = future.result()
tornado.util.TimeoutError: Timeout
distributed.nanny - ERROR - Timed out connecting Nanny '<Nanny: None, threads: 1>' to scheduler 'tcp://172.30.100.4:42246'
Traceback (most recent call last):
  File "/scratch/cnt0024/hmg2840/albert7a/anaconda3/lib/python3.7/site-packages/distributed/nanny.py", line 303, in instantiate
    timedelta(seconds=self.death_timeout), self.process.start()
  File "/scratch/cnt0024/hmg2840/albert7a/anaconda3/lib/python3.7/site-packages/tornado/gen.py", line 729, in run
    value = future.result()
tornado.util.TimeoutError: Timeout
distributed.nanny - ERROR - Timed out connecting Nanny '<Nanny: None, threads: 1>' to scheduler 'tcp://172.30.100.4:42246'
Traceback (most recent call last):
  File "/scratch/cnt0024/hmg2840/albert7a/anaconda3/lib/python3.7/site-packages/distributed/nanny.py", line 303, in instantiate
    timedelta(seconds=self.death_timeout), self.process.start()
  File "/scratch/cnt0024/hmg2840/albert7a/anaconda3/lib/python3.7/site-packages/tornado/gen.py", line 729, in run
    value = future.result()
tornado.util.TimeoutError: Timeout
distributed.nanny - WARNING - Worker process 2280 was killed by signal 15
distributed.nanny - WARNING - Worker process 2284 was killed by signal 15
distributed.nanny - WARNING - Worker process 2282 was killed by signal 15
distributed.nanny - WARNING - Worker process still alive after 47 seconds, killing
distributed.nanny - WARNING - Worker process still alive after 47 seconds, killing
distributed.nanny - WARNING - Worker process still alive after 47 seconds, killing
distributed.nanny - WARNING - Worker process still alive after 47 seconds, killing
distributed.nanny - WARNING - Worker process still alive after 47 seconds, killing
distributed.nanny - WARNING - Worker process still alive after 47 seconds, killing
distributed.nanny - WARNING - Worker process still alive after 47 seconds, killing
distributed.nanny - WARNING - Worker process still alive after 47 seconds, killing
distributed.nanny - WARNING - Worker process still alive after 47 seconds, killing
distributed.nanny - WARNING - Worker process still alive after 47 seconds, killing
distributed.nanny - WARNING - Worker process still alive after 47 seconds, killing
distributed.nanny - ERROR - Timed out connecting Nanny '<Nanny: None, threads: 1>' to scheduler 'tcp://172.30.100.4:42246'
Traceback (most recent call last):
  File "/scratch/cnt0024/hmg2840/albert7a/anaconda3/lib/python3.7/site-packages/distributed/nanny.py", line 303, in instantiate
    timedelta(seconds=self.death_timeout), self.process.start()
  File "/scratch/cnt0024/hmg2840/albert7a/anaconda3/lib/python3.7/site-packages/tornado/gen.py", line 729, in run
    value = future.result()
tornado.util.TimeoutError: Timeout
distributed.nanny - ERROR - Timed out connecting Nanny '<Nanny: None, threads: 1>' to scheduler 'tcp://172.30.100.4:42246'
Traceback (most recent call last):
  File "/scratch/cnt0024/hmg2840/albert7a/anaconda3/lib/python3.7/site-packages/distributed/nanny.py", line 303, in instantiate
    timedelta(seconds=self.death_timeout), self.process.start()
  File "/scratch/cnt0024/hmg2840/albert7a/anaconda3/lib/python3.7/site-packages/tornado/gen.py", line 729, in run
    value = future.result()
tornado.util.TimeoutError: Timeout
distributed.nanny - ERROR - Timed out connecting Nanny '<Nanny: None, threads: 1>' to scheduler 'tcp://172.30.100.4:42246'
Traceback (most recent call last):
  File "/scratch/cnt0024/hmg2840/albert7a/anaconda3/lib/python3.7/site-packages/distributed/nanny.py", line 303, in instantiate
    timedelta(seconds=self.death_timeout), self.process.start()
  File "/scratch/cnt0024/hmg2840/albert7a/anaconda3/lib/python3.7/site-packages/tornado/gen.py", line 729, in run
    value = future.result()
tornado.util.TimeoutError: Timeout
distributed.nanny - ERROR - Timed out connecting Nanny '<Nanny: None, threads: 1>' to scheduler 'tcp://172.30.100.4:42246'
Traceback (most recent call last):
  File "/scratch/cnt0024/hmg2840/albert7a/anaconda3/lib/python3.7/site-packages/distributed/nanny.py", line 303, in instantiate
    timedelta(seconds=self.death_timeout), self.process.start()
  File "/scratch/cnt0024/hmg2840/albert7a/anaconda3/lib/python3.7/site-packages/tornado/gen.py", line 729, in run
    value = future.result()
tornado.util.TimeoutError: Timeout
distributed.nanny - ERROR - Timed out connecting Nanny '<Nanny: None, threads: 1>' to scheduler 'tcp://172.30.100.4:42246'
Traceback (most recent call last):
  File "/scratch/cnt0024/hmg2840/albert7a/anaconda3/lib/python3.7/site-packages/distributed/nanny.py", line 303, in instantiate
    timedelta(seconds=self.death_timeout), self.process.start()
  File "/scratch/cnt0024/hmg2840/albert7a/anaconda3/lib/python3.7/site-packages/tornado/gen.py", line 729, in run
    value = future.result()
tornado.util.TimeoutError: Timeout
distributed.nanny - ERROR - Timed out connecting Nanny '<Nanny: None, threads: 1>' to scheduler 'tcp://172.30.100.4:42246'
Traceback (most recent call last):
  File "/scratch/cnt0024/hmg2840/albert7a/anaconda3/lib/python3.7/site-packages/distributed/nanny.py", line 303, in instantiate
    timedelta(seconds=self.death_timeout), self.process.start()
  File "/scratch/cnt0024/hmg2840/albert7a/anaconda3/lib/python3.7/site-packages/tornado/gen.py", line 729, in run
    value = future.result()
tornado.util.TimeoutError: Timeout
distributed.nanny - ERROR - Timed out connecting Nanny '<Nanny: None, threads: 1>' to scheduler 'tcp://172.30.100.4:42246'
Traceback (most recent call last):
  File "/scratch/cnt0024/hmg2840/albert7a/anaconda3/lib/python3.7/site-packages/distributed/nanny.py", line 303, in instantiate
    timedelta(seconds=self.death_timeout), self.process.start()
  File "/scratch/cnt0024/hmg2840/albert7a/anaconda3/lib/python3.7/site-packages/tornado/gen.py", line 729, in run
    value = future.result()
tornado.util.TimeoutError: Timeout
distributed.nanny - ERROR - Timed out connecting Nanny '<Nanny: None, threads: 1>' to scheduler 'tcp://172.30.100.4:42246'
Traceback (most recent call last):
  File "/scratch/cnt0024/hmg2840/albert7a/anaconda3/lib/python3.7/site-packages/distributed/nanny.py", line 303, in instantiate
    timedelta(seconds=self.death_timeout), self.process.start()
  File "/scratch/cnt0024/hmg2840/albert7a/anaconda3/lib/python3.7/site-packages/tornado/gen.py", line 729, in run
    value = future.result()
tornado.util.TimeoutError: Timeout
distributed.nanny - ERROR - Timed out connecting Nanny '<Nanny: None, threads: 1>' to scheduler 'tcp://172.30.100.4:42246'
Traceback (most recent call last):
  File "/scratch/cnt0024/hmg2840/albert7a/anaconda3/lib/python3.7/site-packages/distributed/nanny.py", line 303, in instantiate
    timedelta(seconds=self.death_timeout), self.process.start()
  File "/scratch/cnt0024/hmg2840/albert7a/anaconda3/lib/python3.7/site-packages/tornado/gen.py", line 729, in run
    value = future.result()
tornado.util.TimeoutError: Timeout
distributed.nanny - ERROR - Timed out connecting Nanny '<Nanny: None, threads: 1>' to scheduler 'tcp://172.30.100.4:42246'
Traceback (most recent call last):
  File "/scratch/cnt0024/hmg2840/albert7a/anaconda3/lib/python3.7/site-packages/distributed/nanny.py", line 303, in instantiate
    timedelta(seconds=self.death_timeout), self.process.start()
  File "/scratch/cnt0024/hmg2840/albert7a/anaconda3/lib/python3.7/site-packages/tornado/gen.py", line 729, in run
    value = future.result()
tornado.util.TimeoutError: Timeout
distributed.nanny - ERROR - Timed out connecting Nanny '<Nanny: None, threads: 1>' to scheduler 'tcp://172.30.100.4:42246'
Traceback (most recent call last):
  File "/scratch/cnt0024/hmg2840/albert7a/anaconda3/lib/python3.7/site-packages/distributed/nanny.py", line 303, in instantiate
    timedelta(seconds=self.death_timeout), self.process.start()
  File "/scratch/cnt0024/hmg2840/albert7a/anaconda3/lib/python3.7/site-packages/tornado/gen.py", line 729, in run
    value = future.result()
tornado.util.TimeoutError: Timeout
distributed.nanny - WARNING - Worker process 2286 was killed by signal 15
distributed.nanny - WARNING - Worker process 2290 was killed by signal 15
distributed.nanny - WARNING - Worker process 2288 was killed by signal 15
distributed.nanny - WARNING - Worker process 2296 was killed by signal 15
distributed.nanny - WARNING - Worker process 2298 was killed by signal 15
distributed.nanny - WARNING - Worker process 2302 was killed by signal 15
distributed.nanny - WARNING - Worker process 2278 was killed by signal 15
distributed.nanny - WARNING - Worker process 2292 was killed by signal 15
distributed.nanny - WARNING - Worker process 2308 was killed by signal 15
distributed.nanny - WARNING - Worker process 2305 was killed by signal 15
distributed.nanny - WARNING - Worker process 2294 was killed by signal 15
distributed.nanny - WARNING - Worker process still alive after 47 seconds, killing
distributed.nanny - WARNING - Worker process still alive after 47 seconds, killing
distributed.nanny - WARNING - Worker process still alive after 47 seconds, killing
distributed.nanny - WARNING - Worker process still alive after 47 seconds, killing
distributed.nanny - ERROR - Timed out connecting Nanny '<Nanny: None, threads: 1>' to scheduler 'tcp://172.30.100.4:42246'
Traceback (most recent call last):
  File "/scratch/cnt0024/hmg2840/albert7a/anaconda3/lib/python3.7/site-packages/distributed/nanny.py", line 303, in instantiate
    timedelta(seconds=self.death_timeout), self.process.start()
  File "/scratch/cnt0024/hmg2840/albert7a/anaconda3/lib/python3.7/site-packages/tornado/gen.py", line 729, in run
    value = future.result()
tornado.util.TimeoutError: Timeout
distributed.nanny - ERROR - Timed out connecting Nanny '<Nanny: None, threads: 1>' to scheduler 'tcp://172.30.100.4:42246'
Traceback (most recent call last):
  File "/scratch/cnt0024/hmg2840/albert7a/anaconda3/lib/python3.7/site-packages/distributed/nanny.py", line 303, in instantiate
    timedelta(seconds=self.death_timeout), self.process.start()
  File "/scratch/cnt0024/hmg2840/albert7a/anaconda3/lib/python3.7/site-packages/tornado/gen.py", line 729, in run
    value = future.result()
tornado.util.TimeoutError: Timeout
distributed.nanny - ERROR - Timed out connecting Nanny '<Nanny: None, threads: 1>' to scheduler 'tcp://172.30.100.4:42246'
Traceback (most recent call last):
  File "/scratch/cnt0024/hmg2840/albert7a/anaconda3/lib/python3.7/site-packages/distributed/nanny.py", line 303, in instantiate
    timedelta(seconds=self.death_timeout), self.process.start()
  File "/scratch/cnt0024/hmg2840/albert7a/anaconda3/lib/python3.7/site-packages/tornado/gen.py", line 729, in run
    value = future.result()
tornado.util.TimeoutError: Timeout
distributed.nanny - ERROR - Timed out connecting Nanny '<Nanny: None, threads: 1>' to scheduler 'tcp://172.30.100.4:42246'
Traceback (most recent call last):
  File "/scratch/cnt0024/hmg2840/albert7a/anaconda3/lib/python3.7/site-packages/distributed/nanny.py", line 303, in instantiate
    timedelta(seconds=self.death_timeout), self.process.start()
  File "/scratch/cnt0024/hmg2840/albert7a/anaconda3/lib/python3.7/site-packages/tornado/gen.py", line 729, in run
    value = future.result()
tornado.util.TimeoutError: Timeout
distributed.nanny - WARNING - Worker process 2311 was killed by signal 15
distributed.nanny - WARNING - Worker process 2314 was killed by signal 15
distributed.nanny - WARNING - Worker process 2317 was killed by signal 15
distributed.nanny - WARNING - Worker process 2320 was killed by signal 15
distributed.nanny - WARNING - Worker process still alive after 47 seconds, killing
distributed.nanny - WARNING - Worker process still alive after 47 seconds, killing
distributed.nanny - ERROR - Timed out connecting Nanny '<Nanny: None, threads: 1>' to scheduler 'tcp://172.30.100.4:42246'
Traceback (most recent call last):
  File "/scratch/cnt0024/hmg2840/albert7a/anaconda3/lib/python3.7/site-packages/distributed/nanny.py", line 303, in instantiate
    timedelta(seconds=self.death_timeout), self.process.start()
  File "/scratch/cnt0024/hmg2840/albert7a/anaconda3/lib/python3.7/site-packages/tornado/gen.py", line 729, in run
    value = future.result()
tornado.util.TimeoutError: Timeout
distributed.nanny - ERROR - Timed out connecting Nanny '<Nanny: None, threads: 1>' to scheduler 'tcp://172.30.100.4:42246'
Traceback (most recent call last):
  File "/scratch/cnt0024/hmg2840/albert7a/anaconda3/lib/python3.7/site-packages/distributed/nanny.py", line 303, in instantiate
    timedelta(seconds=self.death_timeout), self.process.start()
  File "/scratch/cnt0024/hmg2840/albert7a/anaconda3/lib/python3.7/site-packages/tornado/gen.py", line 729, in run
    value = future.result()
tornado.util.TimeoutError: Timeout
distributed.nanny - WARNING - Worker process 2323 was killed by signal 15
distributed.nanny - WARNING - Worker process 2326 was killed by signal 15
distributed.nanny - WARNING - Worker process still alive after 47 seconds, killing
distributed.nanny - ERROR - Timed out connecting Nanny '<Nanny: None, threads: 1>' to scheduler 'tcp://172.30.100.4:42246'
Traceback (most recent call last):
  File "/scratch/cnt0024/hmg2840/albert7a/anaconda3/lib/python3.7/site-packages/distributed/nanny.py", line 303, in instantiate
    timedelta(seconds=self.death_timeout), self.process.start()
  File "/scratch/cnt0024/hmg2840/albert7a/anaconda3/lib/python3.7/site-packages/tornado/gen.py", line 729, in run
    value = future.result()
tornado.util.TimeoutError: Timeout
distributed.nanny - WARNING - Worker process still alive after 47 seconds, killing
distributed.nanny - WARNING - Worker process still alive after 47 seconds, killing
distributed.nanny - WARNING - Worker process still alive after 47 seconds, killing
distributed.nanny - WARNING - Worker process still alive after 47 seconds, killing
distributed.nanny - WARNING - Worker process still alive after 47 seconds, killing
distributed.nanny - WARNING - Worker process still alive after 47 seconds, killing
distributed.nanny - ERROR - Timed out connecting Nanny '<Nanny: None, threads: 1>' to scheduler 'tcp://172.30.100.4:42246'
Traceback (most recent call last):
  File "/scratch/cnt0024/hmg2840/albert7a/anaconda3/lib/python3.7/site-packages/distributed/nanny.py", line 303, in instantiate
    timedelta(seconds=self.death_timeout), self.process.start()
  File "/scratch/cnt0024/hmg2840/albert7a/anaconda3/lib/python3.7/site-packages/tornado/gen.py", line 729, in run
    value = future.result()
tornado.util.TimeoutError: Timeout
distributed.nanny - ERROR - Timed out connecting Nanny '<Nanny: None, threads: 1>' to scheduler 'tcp://172.30.100.4:42246'
Traceback (most recent call last):
  File "/scratch/cnt0024/hmg2840/albert7a/anaconda3/lib/python3.7/site-packages/distributed/nanny.py", line 303, in instantiate
    timedelta(seconds=self.death_timeout), self.process.start()
  File "/scratch/cnt0024/hmg2840/albert7a/anaconda3/lib/python3.7/site-packages/tornado/gen.py", line 729, in run
    value = future.result()
tornado.util.TimeoutError: Timeout
distributed.nanny - ERROR - Timed out connecting Nanny '<Nanny: None, threads: 1>' to scheduler 'tcp://172.30.100.4:42246'
Traceback (most recent call last):
  File "/scratch/cnt0024/hmg2840/albert7a/anaconda3/lib/python3.7/site-packages/distributed/nanny.py", line 303, in instantiate
    timedelta(seconds=self.death_timeout), self.process.start()
  File "/scratch/cnt0024/hmg2840/albert7a/anaconda3/lib/python3.7/site-packages/tornado/gen.py", line 729, in run
    value = future.result()
tornado.util.TimeoutError: Timeout
distributed.nanny - ERROR - Timed out connecting Nanny '<Nanny: None, threads: 1>' to scheduler 'tcp://172.30.100.4:42246'
Traceback (most recent call last):
  File "/scratch/cnt0024/hmg2840/albert7a/anaconda3/lib/python3.7/site-packages/distributed/nanny.py", line 303, in instantiate
    timedelta(seconds=self.death_timeout), self.process.start()
  File "/scratch/cnt0024/hmg2840/albert7a/anaconda3/lib/python3.7/site-packages/tornado/gen.py", line 729, in run
    value = future.result()
tornado.util.TimeoutError: Timeout
distributed.nanny - ERROR - Timed out connecting Nanny '<Nanny: None, threads: 1>' to scheduler 'tcp://172.30.100.4:42246'
Traceback (most recent call last):
  File "/scratch/cnt0024/hmg2840/albert7a/anaconda3/lib/python3.7/site-packages/distributed/nanny.py", line 303, in instantiate
    timedelta(seconds=self.death_timeout), self.process.start()
  File "/scratch/cnt0024/hmg2840/albert7a/anaconda3/lib/python3.7/site-packages/tornado/gen.py", line 729, in run
    value = future.result()
tornado.util.TimeoutError: Timeout
distributed.nanny - ERROR - Timed out connecting Nanny '<Nanny: None, threads: 1>' to scheduler 'tcp://172.30.100.4:42246'
Traceback (most recent call last):
  File "/scratch/cnt0024/hmg2840/albert7a/anaconda3/lib/python3.7/site-packages/distributed/nanny.py", line 303, in instantiate
    timedelta(seconds=self.death_timeout), self.process.start()
  File "/scratch/cnt0024/hmg2840/albert7a/anaconda3/lib/python3.7/site-packages/tornado/gen.py", line 729, in run
    value = future.result()
tornado.util.TimeoutError: Timeout
tornado.application - ERROR - Multiple exceptions in yield list
Traceback (most recent call last):
  File "/scratch/cnt0024/hmg2840/albert7a/anaconda3/lib/python3.7/site-packages/tornado/gen.py", line 501, in callback
    result_list.append(f.result())
  File "/scratch/cnt0024/hmg2840/albert7a/anaconda3/lib/python3.7/asyncio/tasks.py", line 603, in _wrap_awaitable
    return (yield from awaitable.__await__())
  File "/scratch/cnt0024/hmg2840/albert7a/anaconda3/lib/python3.7/site-packages/tornado/gen.py", line 736, in run
    yielded = self.gen.throw(*exc_info)  # type: ignore
  File "/scratch/cnt0024/hmg2840/albert7a/anaconda3/lib/python3.7/site-packages/distributed/nanny.py", line 224, in _start
    response = yield self.instantiate()
  File "/scratch/cnt0024/hmg2840/albert7a/anaconda3/lib/python3.7/site-packages/tornado/gen.py", line 729, in run
    value = future.result()
  File "/scratch/cnt0024/hmg2840/albert7a/anaconda3/lib/python3.7/site-packages/tornado/gen.py", line 742, in run
    yielded = self.gen.send(value)
  File "/scratch/cnt0024/hmg2840/albert7a/anaconda3/lib/python3.7/site-packages/distributed/nanny.py", line 303, in instantiate
    timedelta(seconds=self.death_timeout), self.process.start()
  File "/scratch/cnt0024/hmg2840/albert7a/anaconda3/lib/python3.7/site-packages/tornado/gen.py", line 729, in run
    value = future.result()
tornado.util.TimeoutError: Timeout
tornado.application - ERROR - Multiple exceptions in yield list
Traceback (most recent call last):
  File "/scratch/cnt0024/hmg2840/albert7a/anaconda3/lib/python3.7/site-packages/tornado/gen.py", line 501, in callback
    result_list.append(f.result())
  File "/scratch/cnt0024/hmg2840/albert7a/anaconda3/lib/python3.7/asyncio/tasks.py", line 603, in _wrap_awaitable
    return (yield from awaitable.__await__())
  File "/scratch/cnt0024/hmg2840/albert7a/anaconda3/lib/python3.7/site-packages/tornado/gen.py", line 736, in run
    yielded = self.gen.throw(*exc_info)  # type: ignore
  File "/scratch/cnt0024/hmg2840/albert7a/anaconda3/lib/python3.7/site-packages/distributed/nanny.py", line 224, in _start
    response = yield self.instantiate()
  File "/scratch/cnt0024/hmg2840/albert7a/anaconda3/lib/python3.7/site-packages/tornado/gen.py", line 729, in run
    value = future.result()
  File "/scratch/cnt0024/hmg2840/albert7a/anaconda3/lib/python3.7/site-packages/tornado/gen.py", line 742, in run
    yielded = self.gen.send(value)
  File "/scratch/cnt0024/hmg2840/albert7a/anaconda3/lib/python3.7/site-packages/distributed/nanny.py", line 303, in instantiate
    timedelta(seconds=self.death_timeout), self.process.start()
  File "/scratch/cnt0024/hmg2840/albert7a/anaconda3/lib/python3.7/site-packages/tornado/gen.py", line 729, in run
    value = future.result()
tornado.util.TimeoutError: Timeout
tornado.application - ERROR - Multiple exceptions in yield list
Traceback (most recent call last):
  File "/scratch/cnt0024/hmg2840/albert7a/anaconda3/lib/python3.7/site-packages/tornado/gen.py", line 501, in callback
    result_list.append(f.result())
  File "/scratch/cnt0024/hmg2840/albert7a/anaconda3/lib/python3.7/asyncio/tasks.py", line 603, in _wrap_awaitable
    return (yield from awaitable.__await__())
  File "/scratch/cnt0024/hmg2840/albert7a/anaconda3/lib/python3.7/site-packages/tornado/gen.py", line 736, in run
    yielded = self.gen.throw(*exc_info)  # type: ignore
  File "/scratch/cnt0024/hmg2840/albert7a/anaconda3/lib/python3.7/site-packages/distributed/nanny.py", line 224, in _start
    response = yield self.instantiate()
  File "/scratch/cnt0024/hmg2840/albert7a/anaconda3/lib/python3.7/site-packages/tornado/gen.py", line 729, in run
    value = future.result()
  File "/scratch/cnt0024/hmg2840/albert7a/anaconda3/lib/python3.7/site-packages/tornado/gen.py", line 742, in run
    yielded = self.gen.send(value)
  File "/scratch/cnt0024/hmg2840/albert7a/anaconda3/lib/python3.7/site-packages/distributed/nanny.py", line 303, in instantiate
    timedelta(seconds=self.death_timeout), self.process.start()
  File "/scratch/cnt0024/hmg2840/albert7a/anaconda3/lib/python3.7/site-packages/tornado/gen.py", line 729, in run
    value = future.result()
tornado.util.TimeoutError: Timeout
tornado.application - ERROR - Multiple exceptions in yield list
Traceback (most recent call last):
  File "/scratch/cnt0024/hmg2840/albert7a/anaconda3/lib/python3.7/site-packages/tornado/gen.py", line 501, in callback
    result_list.append(f.result())
  File "/scratch/cnt0024/hmg2840/albert7a/anaconda3/lib/python3.7/asyncio/tasks.py", line 603, in _wrap_awaitable
    return (yield from awaitable.__await__())
  File "/scratch/cnt0024/hmg2840/albert7a/anaconda3/lib/python3.7/site-packages/tornado/gen.py", line 736, in run
    yielded = self.gen.throw(*exc_info)  # type: ignore
  File "/scratch/cnt0024/hmg2840/albert7a/anaconda3/lib/python3.7/site-packages/distributed/nanny.py", line 224, in _start
    response = yield self.instantiate()
  File "/scratch/cnt0024/hmg2840/albert7a/anaconda3/lib/python3.7/site-packages/tornado/gen.py", line 729, in run
    value = future.result()
  File "/scratch/cnt0024/hmg2840/albert7a/anaconda3/lib/python3.7/site-packages/tornado/gen.py", line 742, in run
    yielded = self.gen.send(value)
  File "/scratch/cnt0024/hmg2840/albert7a/anaconda3/lib/python3.7/site-packages/distributed/nanny.py", line 303, in instantiate
    timedelta(seconds=self.death_timeout), self.process.start()
  File "/scratch/cnt0024/hmg2840/albert7a/anaconda3/lib/python3.7/site-packages/tornado/gen.py", line 729, in run
    value = future.result()
tornado.util.TimeoutError: Timeout
tornado.application - ERROR - Multiple exceptions in yield list
Traceback (most recent call last):
  File "/scratch/cnt0024/hmg2840/albert7a/anaconda3/lib/python3.7/site-packages/tornado/gen.py", line 501, in callback
    result_list.append(f.result())
  File "/scratch/cnt0024/hmg2840/albert7a/anaconda3/lib/python3.7/asyncio/tasks.py", line 603, in _wrap_awaitable
    return (yield from awaitable.__await__())
  File "/scratch/cnt0024/hmg2840/albert7a/anaconda3/lib/python3.7/site-packages/tornado/gen.py", line 736, in run
    yielded = self.gen.throw(*exc_info)  # type: ignore
  File "/scratch/cnt0024/hmg2840/albert7a/anaconda3/lib/python3.7/site-packages/distributed/nanny.py", line 224, in _start
    response = yield self.instantiate()
  File "/scratch/cnt0024/hmg2840/albert7a/anaconda3/lib/python3.7/site-packages/tornado/gen.py", line 729, in run
    value = future.result()
  File "/scratch/cnt0024/hmg2840/albert7a/anaconda3/lib/python3.7/site-packages/tornado/gen.py", line 742, in run
    yielded = self.gen.send(value)
  File "/scratch/cnt0024/hmg2840/albert7a/anaconda3/lib/python3.7/site-packages/distributed/nanny.py", line 303, in instantiate
    timedelta(seconds=self.death_timeout), self.process.start()
  File "/scratch/cnt0024/hmg2840/albert7a/anaconda3/lib/python3.7/site-packages/tornado/gen.py", line 729, in run
    value = future.result()
tornado.util.TimeoutError: Timeout
tornado.application - ERROR - Multiple exceptions in yield list
Traceback (most recent call last):
  File "/scratch/cnt0024/hmg2840/albert7a/anaconda3/lib/python3.7/site-packages/tornado/gen.py", line 501, in callback
    result_list.append(f.result())
  File "/scratch/cnt0024/hmg2840/albert7a/anaconda3/lib/python3.7/asyncio/tasks.py", line 603, in _wrap_awaitable
    return (yield from awaitable.__await__())
  File "/scratch/cnt0024/hmg2840/albert7a/anaconda3/lib/python3.7/site-packages/tornado/gen.py", line 736, in run
    yielded = self.gen.throw(*exc_info)  # type: ignore
  File "/scratch/cnt0024/hmg2840/albert7a/anaconda3/lib/python3.7/site-packages/distributed/nanny.py", line 224, in _start
    response = yield self.instantiate()
  File "/scratch/cnt0024/hmg2840/albert7a/anaconda3/lib/python3.7/site-packages/tornado/gen.py", line 729, in run
    value = future.result()
  File "/scratch/cnt0024/hmg2840/albert7a/anaconda3/lib/python3.7/site-packages/tornado/gen.py", line 742, in run
    yielded = self.gen.send(value)
  File "/scratch/cnt0024/hmg2840/albert7a/anaconda3/lib/python3.7/site-packages/distributed/nanny.py", line 303, in instantiate
    timedelta(seconds=self.death_timeout), self.process.start()
  File "/scratch/cnt0024/hmg2840/albert7a/anaconda3/lib/python3.7/site-packages/tornado/gen.py", line 729, in run
    value = future.result()
tornado.util.TimeoutError: Timeout
tornado.application - ERROR - Multiple exceptions in yield list
Traceback (most recent call last):
  File "/scratch/cnt0024/hmg2840/albert7a/anaconda3/lib/python3.7/site-packages/tornado/gen.py", line 501, in callback
    result_list.append(f.result())
  File "/scratch/cnt0024/hmg2840/albert7a/anaconda3/lib/python3.7/asyncio/tasks.py", line 603, in _wrap_awaitable
    return (yield from awaitable.__await__())
  File "/scratch/cnt0024/hmg2840/albert7a/anaconda3/lib/python3.7/site-packages/tornado/gen.py", line 736, in run
    yielded = self.gen.throw(*exc_info)  # type: ignore
  File "/scratch/cnt0024/hmg2840/albert7a/anaconda3/lib/python3.7/site-packages/distributed/nanny.py", line 224, in _start
    response = yield self.instantiate()
  File "/scratch/cnt0024/hmg2840/albert7a/anaconda3/lib/python3.7/site-packages/tornado/gen.py", line 729, in run
    value = future.result()
  File "/scratch/cnt0024/hmg2840/albert7a/anaconda3/lib/python3.7/site-packages/tornado/gen.py", line 742, in run
    yielded = self.gen.send(value)
  File "/scratch/cnt0024/hmg2840/albert7a/anaconda3/lib/python3.7/site-packages/distributed/nanny.py", line 303, in instantiate
    timedelta(seconds=self.death_timeout), self.process.start()
  File "/scratch/cnt0024/hmg2840/albert7a/anaconda3/lib/python3.7/site-packages/tornado/gen.py", line 729, in run
    value = future.result()
tornado.util.TimeoutError: Timeout
tornado.application - ERROR - Multiple exceptions in yield list
Traceback (most recent call last):
  File "/scratch/cnt0024/hmg2840/albert7a/anaconda3/lib/python3.7/site-packages/tornado/gen.py", line 501, in callback
    result_list.append(f.result())
  File "/scratch/cnt0024/hmg2840/albert7a/anaconda3/lib/python3.7/asyncio/tasks.py", line 603, in _wrap_awaitable
    return (yield from awaitable.__await__())
  File "/scratch/cnt0024/hmg2840/albert7a/anaconda3/lib/python3.7/site-packages/tornado/gen.py", line 736, in run
    yielded = self.gen.throw(*exc_info)  # type: ignore
  File "/scratch/cnt0024/hmg2840/albert7a/anaconda3/lib/python3.7/site-packages/distributed/nanny.py", line 224, in _start
    response = yield self.instantiate()
  File "/scratch/cnt0024/hmg2840/albert7a/anaconda3/lib/python3.7/site-packages/tornado/gen.py", line 729, in run
    value = future.result()
  File "/scratch/cnt0024/hmg2840/albert7a/anaconda3/lib/python3.7/site-packages/tornado/gen.py", line 742, in run
    yielded = self.gen.send(value)
  File "/scratch/cnt0024/hmg2840/albert7a/anaconda3/lib/python3.7/site-packages/distributed/nanny.py", line 303, in instantiate
    timedelta(seconds=self.death_timeout), self.process.start()
  File "/scratch/cnt0024/hmg2840/albert7a/anaconda3/lib/python3.7/site-packages/tornado/gen.py", line 729, in run
    value = future.result()
tornado.util.TimeoutError: Timeout
tornado.application - ERROR - Multiple exceptions in yield list
Traceback (most recent call last):
  File "/scratch/cnt0024/hmg2840/albert7a/anaconda3/lib/python3.7/site-packages/tornado/gen.py", line 501, in callback
    result_list.append(f.result())
  File "/scratch/cnt0024/hmg2840/albert7a/anaconda3/lib/python3.7/asyncio/tasks.py", line 603, in _wrap_awaitable
    return (yield from awaitable.__await__())
  File "/scratch/cnt0024/hmg2840/albert7a/anaconda3/lib/python3.7/site-packages/tornado/gen.py", line 736, in run
    yielded = self.gen.throw(*exc_info)  # type: ignore
  File "/scratch/cnt0024/hmg2840/albert7a/anaconda3/lib/python3.7/site-packages/distributed/nanny.py", line 224, in _start
    response = yield self.instantiate()
  File "/scratch/cnt0024/hmg2840/albert7a/anaconda3/lib/python3.7/site-packages/tornado/gen.py", line 729, in run
    value = future.result()
  File "/scratch/cnt0024/hmg2840/albert7a/anaconda3/lib/python3.7/site-packages/tornado/gen.py", line 742, in run
    yielded = self.gen.send(value)
  File "/scratch/cnt0024/hmg2840/albert7a/anaconda3/lib/python3.7/site-packages/distributed/nanny.py", line 303, in instantiate
    timedelta(seconds=self.death_timeout), self.process.start()
  File "/scratch/cnt0024/hmg2840/albert7a/anaconda3/lib/python3.7/site-packages/tornado/gen.py", line 729, in run
    value = future.result()
tornado.util.TimeoutError: Timeout
tornado.application - ERROR - Multiple exceptions in yield list
Traceback (most recent call last):
  File "/scratch/cnt0024/hmg2840/albert7a/anaconda3/lib/python3.7/site-packages/tornado/gen.py", line 501, in callback
    result_list.append(f.result())
  File "/scratch/cnt0024/hmg2840/albert7a/anaconda3/lib/python3.7/asyncio/tasks.py", line 603, in _wrap_awaitable
    return (yield from awaitable.__await__())
  File "/scratch/cnt0024/hmg2840/albert7a/anaconda3/lib/python3.7/site-packages/tornado/gen.py", line 736, in run
    yielded = self.gen.throw(*exc_info)  # type: ignore
  File "/scratch/cnt0024/hmg2840/albert7a/anaconda3/lib/python3.7/site-packages/distributed/nanny.py", line 224, in _start
    response = yield self.instantiate()
  File "/scratch/cnt0024/hmg2840/albert7a/anaconda3/lib/python3.7/site-packages/tornado/gen.py", line 729, in run
    value = future.result()
  File "/scratch/cnt0024/hmg2840/albert7a/anaconda3/lib/python3.7/site-packages/tornado/gen.py", line 742, in run
    yielded = self.gen.send(value)
  File "/scratch/cnt0024/hmg2840/albert7a/anaconda3/lib/python3.7/site-packages/distributed/nanny.py", line 303, in instantiate
    timedelta(seconds=self.death_timeout), self.process.start()
  File "/scratch/cnt0024/hmg2840/albert7a/anaconda3/lib/python3.7/site-packages/tornado/gen.py", line 729, in run
    value = future.result()
tornado.util.TimeoutError: Timeout
tornado.application - ERROR - Multiple exceptions in yield list
Traceback (most recent call last):
  File "/scratch/cnt0024/hmg2840/albert7a/anaconda3/lib/python3.7/site-packages/tornado/gen.py", line 501, in callback
    result_list.append(f.result())
  File "/scratch/cnt0024/hmg2840/albert7a/anaconda3/lib/python3.7/asyncio/tasks.py", line 603, in _wrap_awaitable
    return (yield from awaitable.__await__())
  File "/scratch/cnt0024/hmg2840/albert7a/anaconda3/lib/python3.7/site-packages/tornado/gen.py", line 736, in run
    yielded = self.gen.throw(*exc_info)  # type: ignore
  File "/scratch/cnt0024/hmg2840/albert7a/anaconda3/lib/python3.7/site-packages/distributed/nanny.py", line 224, in _start
    response = yield self.instantiate()
  File "/scratch/cnt0024/hmg2840/albert7a/anaconda3/lib/python3.7/site-packages/tornado/gen.py", line 729, in run
    value = future.result()
  File "/scratch/cnt0024/hmg2840/albert7a/anaconda3/lib/python3.7/site-packages/tornado/gen.py", line 742, in run
    yielded = self.gen.send(value)
  File "/scratch/cnt0024/hmg2840/albert7a/anaconda3/lib/python3.7/site-packages/distributed/nanny.py", line 303, in instantiate
    timedelta(seconds=self.death_timeout), self.process.start()
  File "/scratch/cnt0024/hmg2840/albert7a/anaconda3/lib/python3.7/site-packages/tornado/gen.py", line 729, in run
    value = future.result()
tornado.util.TimeoutError: Timeout
tornado.application - ERROR - Multiple exceptions in yield list
Traceback (most recent call last):
  File "/scratch/cnt0024/hmg2840/albert7a/anaconda3/lib/python3.7/site-packages/tornado/gen.py", line 501, in callback
    result_list.append(f.result())
  File "/scratch/cnt0024/hmg2840/albert7a/anaconda3/lib/python3.7/asyncio/tasks.py", line 603, in _wrap_awaitable
    return (yield from awaitable.__await__())
  File "/scratch/cnt0024/hmg2840/albert7a/anaconda3/lib/python3.7/site-packages/tornado/gen.py", line 736, in run
    yielded = self.gen.throw(*exc_info)  # type: ignore
  File "/scratch/cnt0024/hmg2840/albert7a/anaconda3/lib/python3.7/site-packages/distributed/nanny.py", line 224, in _start
    response = yield self.instantiate()
  File "/scratch/cnt0024/hmg2840/albert7a/anaconda3/lib/python3.7/site-packages/tornado/gen.py", line 729, in run
    value = future.result()
  File "/scratch/cnt0024/hmg2840/albert7a/anaconda3/lib/python3.7/site-packages/tornado/gen.py", line 742, in run
    yielded = self.gen.send(value)
  File "/scratch/cnt0024/hmg2840/albert7a/anaconda3/lib/python3.7/site-packages/distributed/nanny.py", line 303, in instantiate
    timedelta(seconds=self.death_timeout), self.process.start()
  File "/scratch/cnt0024/hmg2840/albert7a/anaconda3/lib/python3.7/site-packages/tornado/gen.py", line 729, in run
    value = future.result()
tornado.util.TimeoutError: Timeout
tornado.application - ERROR - Multiple exceptions in yield list
Traceback (most recent call last):
  File "/scratch/cnt0024/hmg2840/albert7a/anaconda3/lib/python3.7/site-packages/tornado/gen.py", line 501, in callback
    result_list.append(f.result())
  File "/scratch/cnt0024/hmg2840/albert7a/anaconda3/lib/python3.7/asyncio/tasks.py", line 603, in _wrap_awaitable
    return (yield from awaitable.__await__())
  File "/scratch/cnt0024/hmg2840/albert7a/anaconda3/lib/python3.7/site-packages/tornado/gen.py", line 736, in run
    yielded = self.gen.throw(*exc_info)  # type: ignore
  File "/scratch/cnt0024/hmg2840/albert7a/anaconda3/lib/python3.7/site-packages/distributed/nanny.py", line 224, in _start
    response = yield self.instantiate()
  File "/scratch/cnt0024/hmg2840/albert7a/anaconda3/lib/python3.7/site-packages/tornado/gen.py", line 729, in run
    value = future.result()
  File "/scratch/cnt0024/hmg2840/albert7a/anaconda3/lib/python3.7/site-packages/tornado/gen.py", line 742, in run
    yielded = self.gen.send(value)
  File "/scratch/cnt0024/hmg2840/albert7a/anaconda3/lib/python3.7/site-packages/distributed/nanny.py", line 303, in instantiate
    timedelta(seconds=self.death_timeout), self.process.start()
  File "/scratch/cnt0024/hmg2840/albert7a/anaconda3/lib/python3.7/site-packages/tornado/gen.py", line 729, in run
    value = future.result()
tornado.util.TimeoutError: Timeout
tornado.application - ERROR - Multiple exceptions in yield list
Traceback (most recent call last):
  File "/scratch/cnt0024/hmg2840/albert7a/anaconda3/lib/python3.7/site-packages/tornado/gen.py", line 501, in callback
    result_list.append(f.result())
  File "/scratch/cnt0024/hmg2840/albert7a/anaconda3/lib/python3.7/asyncio/tasks.py", line 603, in _wrap_awaitable
    return (yield from awaitable.__await__())
  File "/scratch/cnt0024/hmg2840/albert7a/anaconda3/lib/python3.7/site-packages/tornado/gen.py", line 736, in run
    yielded = self.gen.throw(*exc_info)  # type: ignore
  File "/scratch/cnt0024/hmg2840/albert7a/anaconda3/lib/python3.7/site-packages/distributed/nanny.py", line 224, in _start
    response = yield self.instantiate()
  File "/scratch/cnt0024/hmg2840/albert7a/anaconda3/lib/python3.7/site-packages/tornado/gen.py", line 729, in run
    value = future.result()
  File "/scratch/cnt0024/hmg2840/albert7a/anaconda3/lib/python3.7/site-packages/tornado/gen.py", line 742, in run
    yielded = self.gen.send(value)
  File "/scratch/cnt0024/hmg2840/albert7a/anaconda3/lib/python3.7/site-packages/distributed/nanny.py", line 303, in instantiate
    timedelta(seconds=self.death_timeout), self.process.start()
  File "/scratch/cnt0024/hmg2840/albert7a/anaconda3/lib/python3.7/site-packages/tornado/gen.py", line 729, in run
    value = future.result()
tornado.util.TimeoutError: Timeout
tornado.application - ERROR - Multiple exceptions in yield list
Traceback (most recent call last):
  File "/scratch/cnt0024/hmg2840/albert7a/anaconda3/lib/python3.7/site-packages/tornado/gen.py", line 501, in callback
    result_list.append(f.result())
  File "/scratch/cnt0024/hmg2840/albert7a/anaconda3/lib/python3.7/asyncio/tasks.py", line 603, in _wrap_awaitable
    return (yield from awaitable.__await__())
  File "/scratch/cnt0024/hmg2840/albert7a/anaconda3/lib/python3.7/site-packages/tornado/gen.py", line 736, in run
    yielded = self.gen.throw(*exc_info)  # type: ignore
  File "/scratch/cnt0024/hmg2840/albert7a/anaconda3/lib/python3.7/site-packages/distributed/nanny.py", line 224, in _start
    response = yield self.instantiate()
  File "/scratch/cnt0024/hmg2840/albert7a/anaconda3/lib/python3.7/site-packages/tornado/gen.py", line 729, in run
    value = future.result()
  File "/scratch/cnt0024/hmg2840/albert7a/anaconda3/lib/python3.7/site-packages/tornado/gen.py", line 742, in run
    yielded = self.gen.send(value)
  File "/scratch/cnt0024/hmg2840/albert7a/anaconda3/lib/python3.7/site-packages/distributed/nanny.py", line 303, in instantiate
    timedelta(seconds=self.death_timeout), self.process.start()
  File "/scratch/cnt0024/hmg2840/albert7a/anaconda3/lib/python3.7/site-packages/tornado/gen.py", line 729, in run
    value = future.result()
tornado.util.TimeoutError: Timeout
tornado.application - ERROR - Multiple exceptions in yield list
Traceback (most recent call last):
  File "/scratch/cnt0024/hmg2840/albert7a/anaconda3/lib/python3.7/site-packages/tornado/gen.py", line 501, in callback
    result_list.append(f.result())
  File "/scratch/cnt0024/hmg2840/albert7a/anaconda3/lib/python3.7/asyncio/tasks.py", line 603, in _wrap_awaitable
    return (yield from awaitable.__await__())
  File "/scratch/cnt0024/hmg2840/albert7a/anaconda3/lib/python3.7/site-packages/tornado/gen.py", line 736, in run
    yielded = self.gen.throw(*exc_info)  # type: ignore
  File "/scratch/cnt0024/hmg2840/albert7a/anaconda3/lib/python3.7/site-packages/distributed/nanny.py", line 224, in _start
    response = yield self.instantiate()
  File "/scratch/cnt0024/hmg2840/albert7a/anaconda3/lib/python3.7/site-packages/tornado/gen.py", line 729, in run
    value = future.result()
  File "/scratch/cnt0024/hmg2840/albert7a/anaconda3/lib/python3.7/site-packages/tornado/gen.py", line 742, in run
    yielded = self.gen.send(value)
  File "/scratch/cnt0024/hmg2840/albert7a/anaconda3/lib/python3.7/site-packages/distributed/nanny.py", line 303, in instantiate
    timedelta(seconds=self.death_timeout), self.process.start()
  File "/scratch/cnt0024/hmg2840/albert7a/anaconda3/lib/python3.7/site-packages/tornado/gen.py", line 729, in run
    value = future.result()
tornado.util.TimeoutError: Timeout
tornado.application - ERROR - Multiple exceptions in yield list
Traceback (most recent call last):
  File "/scratch/cnt0024/hmg2840/albert7a/anaconda3/lib/python3.7/site-packages/tornado/gen.py", line 501, in callback
    result_list.append(f.result())
  File "/scratch/cnt0024/hmg2840/albert7a/anaconda3/lib/python3.7/asyncio/tasks.py", line 603, in _wrap_awaitable
    return (yield from awaitable.__await__())
  File "/scratch/cnt0024/hmg2840/albert7a/anaconda3/lib/python3.7/site-packages/tornado/gen.py", line 736, in run
    yielded = self.gen.throw(*exc_info)  # type: ignore
  File "/scratch/cnt0024/hmg2840/albert7a/anaconda3/lib/python3.7/site-packages/distributed/nanny.py", line 224, in _start
    response = yield self.instantiate()
  File "/scratch/cnt0024/hmg2840/albert7a/anaconda3/lib/python3.7/site-packages/tornado/gen.py", line 729, in run
    value = future.result()
  File "/scratch/cnt0024/hmg2840/albert7a/anaconda3/lib/python3.7/site-packages/tornado/gen.py", line 742, in run
    yielded = self.gen.send(value)
  File "/scratch/cnt0024/hmg2840/albert7a/anaconda3/lib/python3.7/site-packages/distributed/nanny.py", line 303, in instantiate
    timedelta(seconds=self.death_timeout), self.process.start()
  File "/scratch/cnt0024/hmg2840/albert7a/anaconda3/lib/python3.7/site-packages/tornado/gen.py", line 729, in run
    value = future.result()
tornado.util.TimeoutError: Timeout
tornado.application - ERROR - Multiple exceptions in yield list
Traceback (most recent call last):
  File "/scratch/cnt0024/hmg2840/albert7a/anaconda3/lib/python3.7/site-packages/tornado/gen.py", line 501, in callback
    result_list.append(f.result())
  File "/scratch/cnt0024/hmg2840/albert7a/anaconda3/lib/python3.7/asyncio/tasks.py", line 603, in _wrap_awaitable
    return (yield from awaitable.__await__())
  File "/scratch/cnt0024/hmg2840/albert7a/anaconda3/lib/python3.7/site-packages/tornado/gen.py", line 736, in run
    yielded = self.gen.throw(*exc_info)  # type: ignore
  File "/scratch/cnt0024/hmg2840/albert7a/anaconda3/lib/python3.7/site-packages/distributed/nanny.py", line 224, in _start
    response = yield self.instantiate()
  File "/scratch/cnt0024/hmg2840/albert7a/anaconda3/lib/python3.7/site-packages/tornado/gen.py", line 729, in run
    value = future.result()
  File "/scratch/cnt0024/hmg2840/albert7a/anaconda3/lib/python3.7/site-packages/tornado/gen.py", line 742, in run
    yielded = self.gen.send(value)
  File "/scratch/cnt0024/hmg2840/albert7a/anaconda3/lib/python3.7/site-packages/distributed/nanny.py", line 303, in instantiate
    timedelta(seconds=self.death_timeout), self.process.start()
  File "/scratch/cnt0024/hmg2840/albert7a/anaconda3/lib/python3.7/site-packages/tornado/gen.py", line 729, in run
    value = future.result()
tornado.util.TimeoutError: Timeout
tornado.application - ERROR - Multiple exceptions in yield list
Traceback (most recent call last):
  File "/scratch/cnt0024/hmg2840/albert7a/anaconda3/lib/python3.7/site-packages/tornado/gen.py", line 501, in callback
    result_list.append(f.result())
  File "/scratch/cnt0024/hmg2840/albert7a/anaconda3/lib/python3.7/asyncio/tasks.py", line 603, in _wrap_awaitable
    return (yield from awaitable.__await__())
  File "/scratch/cnt0024/hmg2840/albert7a/anaconda3/lib/python3.7/site-packages/tornado/gen.py", line 736, in run
    yielded = self.gen.throw(*exc_info)  # type: ignore
  File "/scratch/cnt0024/hmg2840/albert7a/anaconda3/lib/python3.7/site-packages/distributed/nanny.py", line 224, in _start
    response = yield self.instantiate()
  File "/scratch/cnt0024/hmg2840/albert7a/anaconda3/lib/python3.7/site-packages/tornado/gen.py", line 729, in run
    value = future.result()
  File "/scratch/cnt0024/hmg2840/albert7a/anaconda3/lib/python3.7/site-packages/tornado/gen.py", line 742, in run
    yielded = self.gen.send(value)
  File "/scratch/cnt0024/hmg2840/albert7a/anaconda3/lib/python3.7/site-packages/distributed/nanny.py", line 303, in instantiate
    timedelta(seconds=self.death_timeout), self.process.start()
  File "/scratch/cnt0024/hmg2840/albert7a/anaconda3/lib/python3.7/site-packages/tornado/gen.py", line 729, in run
    value = future.result()
tornado.util.TimeoutError: Timeout
tornado.application - ERROR - Multiple exceptions in yield list
Traceback (most recent call last):
  File "/scratch/cnt0024/hmg2840/albert7a/anaconda3/lib/python3.7/site-packages/tornado/gen.py", line 501, in callback
    result_list.append(f.result())
  File "/scratch/cnt0024/hmg2840/albert7a/anaconda3/lib/python3.7/asyncio/tasks.py", line 603, in _wrap_awaitable
    return (yield from awaitable.__await__())
  File "/scratch/cnt0024/hmg2840/albert7a/anaconda3/lib/python3.7/site-packages/tornado/gen.py", line 736, in run
    yielded = self.gen.throw(*exc_info)  # type: ignore
  File "/scratch/cnt0024/hmg2840/albert7a/anaconda3/lib/python3.7/site-packages/distributed/nanny.py", line 224, in _start
    response = yield self.instantiate()
  File "/scratch/cnt0024/hmg2840/albert7a/anaconda3/lib/python3.7/site-packages/tornado/gen.py", line 729, in run
    value = future.result()
  File "/scratch/cnt0024/hmg2840/albert7a/anaconda3/lib/python3.7/site-packages/tornado/gen.py", line 742, in run
    yielded = self.gen.send(value)
  File "/scratch/cnt0024/hmg2840/albert7a/anaconda3/lib/python3.7/site-packages/distributed/nanny.py", line 303, in instantiate
    timedelta(seconds=self.death_timeout), self.process.start()
  File "/scratch/cnt0024/hmg2840/albert7a/anaconda3/lib/python3.7/site-packages/tornado/gen.py", line 729, in run
    value = future.result()
tornado.util.TimeoutError: Timeout
tornado.application - ERROR - Multiple exceptions in yield list
Traceback (most recent call last):
  File "/scratch/cnt0024/hmg2840/albert7a/anaconda3/lib/python3.7/site-packages/tornado/gen.py", line 501, in callback
    result_list.append(f.result())
  File "/scratch/cnt0024/hmg2840/albert7a/anaconda3/lib/python3.7/asyncio/tasks.py", line 603, in _wrap_awaitable
    return (yield from awaitable.__await__())
  File "/scratch/cnt0024/hmg2840/albert7a/anaconda3/lib/python3.7/site-packages/tornado/gen.py", line 736, in run
    yielded = self.gen.throw(*exc_info)  # type: ignore
  File "/scratch/cnt0024/hmg2840/albert7a/anaconda3/lib/python3.7/site-packages/distributed/nanny.py", line 224, in _start
    response = yield self.instantiate()
  File "/scratch/cnt0024/hmg2840/albert7a/anaconda3/lib/python3.7/site-packages/tornado/gen.py", line 729, in run
    value = future.result()
  File "/scratch/cnt0024/hmg2840/albert7a/anaconda3/lib/python3.7/site-packages/tornado/gen.py", line 742, in run
    yielded = self.gen.send(value)
  File "/scratch/cnt0024/hmg2840/albert7a/anaconda3/lib/python3.7/site-packages/distributed/nanny.py", line 303, in instantiate
    timedelta(seconds=self.death_timeout), self.process.start()
  File "/scratch/cnt0024/hmg2840/albert7a/anaconda3/lib/python3.7/site-packages/tornado/gen.py", line 729, in run
    value = future.result()
tornado.util.TimeoutError: Timeout
tornado.application - ERROR - Multiple exceptions in yield list
Traceback (most recent call last):
  File "/scratch/cnt0024/hmg2840/albert7a/anaconda3/lib/python3.7/site-packages/tornado/gen.py", line 501, in callback
    result_list.append(f.result())
  File "/scratch/cnt0024/hmg2840/albert7a/anaconda3/lib/python3.7/asyncio/tasks.py", line 603, in _wrap_awaitable
    return (yield from awaitable.__await__())
  File "/scratch/cnt0024/hmg2840/albert7a/anaconda3/lib/python3.7/site-packages/tornado/gen.py", line 736, in run
    yielded = self.gen.throw(*exc_info)  # type: ignore
  File "/scratch/cnt0024/hmg2840/albert7a/anaconda3/lib/python3.7/site-packages/distributed/nanny.py", line 224, in _start
    response = yield self.instantiate()
  File "/scratch/cnt0024/hmg2840/albert7a/anaconda3/lib/python3.7/site-packages/tornado/gen.py", line 729, in run
    value = future.result()
  File "/scratch/cnt0024/hmg2840/albert7a/anaconda3/lib/python3.7/site-packages/tornado/gen.py", line 742, in run
    yielded = self.gen.send(value)
  File "/scratch/cnt0024/hmg2840/albert7a/anaconda3/lib/python3.7/site-packages/distributed/nanny.py", line 303, in instantiate
    timedelta(seconds=self.death_timeout), self.process.start()
  File "/scratch/cnt0024/hmg2840/albert7a/anaconda3/lib/python3.7/site-packages/tornado/gen.py", line 729, in run
    value = future.result()
tornado.util.TimeoutError: Timeout
tornado.application - ERROR - Multiple exceptions in yield list
Traceback (most recent call last):
  File "/scratch/cnt0024/hmg2840/albert7a/anaconda3/lib/python3.7/site-packages/tornado/gen.py", line 501, in callback
    result_list.append(f.result())
  File "/scratch/cnt0024/hmg2840/albert7a/anaconda3/lib/python3.7/asyncio/tasks.py", line 603, in _wrap_awaitable
    return (yield from awaitable.__await__())
  File "/scratch/cnt0024/hmg2840/albert7a/anaconda3/lib/python3.7/site-packages/tornado/gen.py", line 736, in run
    yielded = self.gen.throw(*exc_info)  # type: ignore
  File "/scratch/cnt0024/hmg2840/albert7a/anaconda3/lib/python3.7/site-packages/distributed/nanny.py", line 224, in _start
    response = yield self.instantiate()
  File "/scratch/cnt0024/hmg2840/albert7a/anaconda3/lib/python3.7/site-packages/tornado/gen.py", line 729, in run
    value = future.result()
  File "/scratch/cnt0024/hmg2840/albert7a/anaconda3/lib/python3.7/site-packages/tornado/gen.py", line 742, in run
    yielded = self.gen.send(value)
  File "/scratch/cnt0024/hmg2840/albert7a/anaconda3/lib/python3.7/site-packages/distributed/nanny.py", line 303, in instantiate
    timedelta(seconds=self.death_timeout), self.process.start()
  File "/scratch/cnt0024/hmg2840/albert7a/anaconda3/lib/python3.7/site-packages/tornado/gen.py", line 729, in run
    value = future.result()
tornado.util.TimeoutError: Timeout
tornado.application - ERROR - Multiple exceptions in yield list
Traceback (most recent call last):
  File "/scratch/cnt0024/hmg2840/albert7a/anaconda3/lib/python3.7/site-packages/tornado/gen.py", line 501, in callback
    result_list.append(f.result())
  File "/scratch/cnt0024/hmg2840/albert7a/anaconda3/lib/python3.7/asyncio/tasks.py", line 603, in _wrap_awaitable
    return (yield from awaitable.__await__())
  File "/scratch/cnt0024/hmg2840/albert7a/anaconda3/lib/python3.7/site-packages/tornado/gen.py", line 736, in run
    yielded = self.gen.throw(*exc_info)  # type: ignore
  File "/scratch/cnt0024/hmg2840/albert7a/anaconda3/lib/python3.7/site-packages/distributed/nanny.py", line 224, in _start
    response = yield self.instantiate()
  File "/scratch/cnt0024/hmg2840/albert7a/anaconda3/lib/python3.7/site-packages/tornado/gen.py", line 729, in run
    value = future.result()
  File "/scratch/cnt0024/hmg2840/albert7a/anaconda3/lib/python3.7/site-packages/tornado/gen.py", line 742, in run
    yielded = self.gen.send(value)
  File "/scratch/cnt0024/hmg2840/albert7a/anaconda3/lib/python3.7/site-packages/distributed/nanny.py", line 303, in instantiate
    timedelta(seconds=self.death_timeout), self.process.start()
  File "/scratch/cnt0024/hmg2840/albert7a/anaconda3/lib/python3.7/site-packages/tornado/gen.py", line 729, in run
    value = future.result()
tornado.util.TimeoutError: Timeout
tornado.application - ERROR - Multiple exceptions in yield list
Traceback (most recent call last):
  File "/scratch/cnt0024/hmg2840/albert7a/anaconda3/lib/python3.7/site-packages/tornado/gen.py", line 501, in callback
    result_list.append(f.result())
  File "/scratch/cnt0024/hmg2840/albert7a/anaconda3/lib/python3.7/asyncio/tasks.py", line 603, in _wrap_awaitable
    return (yield from awaitable.__await__())
  File "/scratch/cnt0024/hmg2840/albert7a/anaconda3/lib/python3.7/site-packages/tornado/gen.py", line 736, in run
    yielded = self.gen.throw(*exc_info)  # type: ignore
  File "/scratch/cnt0024/hmg2840/albert7a/anaconda3/lib/python3.7/site-packages/distributed/nanny.py", line 224, in _start
    response = yield self.instantiate()
  File "/scratch/cnt0024/hmg2840/albert7a/anaconda3/lib/python3.7/site-packages/tornado/gen.py", line 729, in run
    value = future.result()
  File "/scratch/cnt0024/hmg2840/albert7a/anaconda3/lib/python3.7/site-packages/tornado/gen.py", line 742, in run
    yielded = self.gen.send(value)
  File "/scratch/cnt0024/hmg2840/albert7a/anaconda3/lib/python3.7/site-packages/distributed/nanny.py", line 303, in instantiate
    timedelta(seconds=self.death_timeout), self.process.start()
  File "/scratch/cnt0024/hmg2840/albert7a/anaconda3/lib/python3.7/site-packages/tornado/gen.py", line 729, in run
    value = future.result()
tornado.util.TimeoutError: Timeout
tornado.application - ERROR - Multiple exceptions in yield list
Traceback (most recent call last):
  File "/scratch/cnt0024/hmg2840/albert7a/anaconda3/lib/python3.7/site-packages/tornado/gen.py", line 501, in callback
    result_list.append(f.result())
  File "/scratch/cnt0024/hmg2840/albert7a/anaconda3/lib/python3.7/asyncio/tasks.py", line 603, in _wrap_awaitable
    return (yield from awaitable.__await__())
  File "/scratch/cnt0024/hmg2840/albert7a/anaconda3/lib/python3.7/site-packages/tornado/gen.py", line 736, in run
    yielded = self.gen.throw(*exc_info)  # type: ignore
  File "/scratch/cnt0024/hmg2840/albert7a/anaconda3/lib/python3.7/site-packages/distributed/nanny.py", line 224, in _start
    response = yield self.instantiate()
  File "/scratch/cnt0024/hmg2840/albert7a/anaconda3/lib/python3.7/site-packages/tornado/gen.py", line 729, in run
    value = future.result()
  File "/scratch/cnt0024/hmg2840/albert7a/anaconda3/lib/python3.7/site-packages/tornado/gen.py", line 742, in run
    yielded = self.gen.send(value)
  File "/scratch/cnt0024/hmg2840/albert7a/anaconda3/lib/python3.7/site-packages/distributed/nanny.py", line 303, in instantiate
    timedelta(seconds=self.death_timeout), self.process.start()
  File "/scratch/cnt0024/hmg2840/albert7a/anaconda3/lib/python3.7/site-packages/tornado/gen.py", line 729, in run
    value = future.result()
tornado.util.TimeoutError: Timeout
tornado.application - ERROR - Multiple exceptions in yield list
Traceback (most recent call last):
  File "/scratch/cnt0024/hmg2840/albert7a/anaconda3/lib/python3.7/site-packages/tornado/gen.py", line 501, in callback
    result_list.append(f.result())
  File "/scratch/cnt0024/hmg2840/albert7a/anaconda3/lib/python3.7/asyncio/tasks.py", line 603, in _wrap_awaitable
    return (yield from awaitable.__await__())
  File "/scratch/cnt0024/hmg2840/albert7a/anaconda3/lib/python3.7/site-packages/tornado/gen.py", line 736, in run
    yielded = self.gen.throw(*exc_info)  # type: ignore
  File "/scratch/cnt0024/hmg2840/albert7a/anaconda3/lib/python3.7/site-packages/distributed/nanny.py", line 224, in _start
    response = yield self.instantiate()
  File "/scratch/cnt0024/hmg2840/albert7a/anaconda3/lib/python3.7/site-packages/tornado/gen.py", line 729, in run
    value = future.result()
  File "/scratch/cnt0024/hmg2840/albert7a/anaconda3/lib/python3.7/site-packages/tornado/gen.py", line 742, in run
    yielded = self.gen.send(value)
  File "/scratch/cnt0024/hmg2840/albert7a/anaconda3/lib/python3.7/site-packages/distributed/nanny.py", line 303, in instantiate
    timedelta(seconds=self.death_timeout), self.process.start()
  File "/scratch/cnt0024/hmg2840/albert7a/anaconda3/lib/python3.7/site-packages/tornado/gen.py", line 729, in run
    value = future.result()
tornado.util.TimeoutError: Timeout
distributed.nanny - WARNING - Worker process 2328 was killed by signal 15
distributed.nanny - WARNING - Worker process 2332 was killed by signal 15
distributed.nanny - WARNING - Worker process 2335 was killed by signal 15
distributed.nanny - WARNING - Worker process 2337 was killed by signal 15
distributed.nanny - WARNING - Worker process 2347 was killed by signal 15
distributed.nanny - WARNING - Worker process 2341 was killed by signal 15
distributed.dask_worker - INFO - End worker
Traceback (most recent call last):
  File "/scratch/cnt0024/hmg2840/albert7a/anaconda3/lib/python3.7/runpy.py", line 193, in _run_module_as_main
    "__main__", mod_spec)
  File "/scratch/cnt0024/hmg2840/albert7a/anaconda3/lib/python3.7/runpy.py", line 85, in _run_code
    exec(code, run_globals)
  File "/scratch/cnt0024/hmg2840/albert7a/anaconda3/lib/python3.7/site-packages/distributed/cli/dask_worker.py", line 405, in <module>
    go()
  File "/scratch/cnt0024/hmg2840/albert7a/anaconda3/lib/python3.7/site-packages/distributed/cli/dask_worker.py", line 401, in go
    main()
  File "/scratch/cnt0024/hmg2840/albert7a/anaconda3/lib/python3.7/site-packages/click/core.py", line 764, in __call__
    return self.main(*args, **kwargs)
  File "/scratch/cnt0024/hmg2840/albert7a/anaconda3/lib/python3.7/site-packages/click/core.py", line 717, in main
    rv = self.invoke(ctx)
  File "/scratch/cnt0024/hmg2840/albert7a/anaconda3/lib/python3.7/site-packages/click/core.py", line 956, in invoke
    return ctx.invoke(self.callback, **ctx.params)
  File "/scratch/cnt0024/hmg2840/albert7a/anaconda3/lib/python3.7/site-packages/click/core.py", line 555, in invoke
    return callback(*args, **kwargs)
  File "/scratch/cnt0024/hmg2840/albert7a/anaconda3/lib/python3.7/site-packages/distributed/cli/dask_worker.py", line 392, in main
    raise TimeoutError("Timed out starting worker.") from None
tornado.util.TimeoutError: Timed out starting worker.
/scratch/cnt0024/hmg2840/albert7a/anaconda3/lib/python3.7/site-packages/distributed/utils.py:136: RuntimeWarning: Couldn't detect a suitable IP address for reaching '8.8.8.8', defaulting to '127.0.0.1': [Errno 101] Network is unreachable
  RuntimeWarning,
