/scratch/cnt0024/hmg2840/albert7a/anaconda3/lib/python3.7/site-packages/distributed/utils.py:136: RuntimeWarning: Couldn't detect a suitable IP address for reaching '8.8.8.8', defaulting to '127.0.0.1': [Errno 101] Network is unreachable
  RuntimeWarning,
distributed.nanny - INFO -         Start Nanny at: 'tcp://172.30.9.50:41169'
distributed.nanny - INFO -         Start Nanny at: 'tcp://172.30.9.50:41812'
distributed.nanny - INFO -         Start Nanny at: 'tcp://172.30.9.50:45683'
distributed.nanny - INFO -         Start Nanny at: 'tcp://172.30.9.50:33722'
distributed.nanny - INFO -         Start Nanny at: 'tcp://172.30.9.50:37919'
distributed.nanny - INFO -         Start Nanny at: 'tcp://172.30.9.50:45587'
distributed.nanny - INFO -         Start Nanny at: 'tcp://172.30.9.50:44563'
distributed.nanny - INFO -         Start Nanny at: 'tcp://172.30.9.50:36681'
distributed.nanny - INFO -         Start Nanny at: 'tcp://172.30.9.50:45443'
distributed.nanny - INFO -         Start Nanny at: 'tcp://172.30.9.50:36116'
distributed.nanny - INFO -         Start Nanny at: 'tcp://172.30.9.50:35951'
distributed.nanny - INFO -         Start Nanny at: 'tcp://172.30.9.50:34834'
distributed.nanny - INFO -         Start Nanny at: 'tcp://172.30.9.50:35488'
distributed.nanny - INFO -         Start Nanny at: 'tcp://172.30.9.50:34969'
distributed.nanny - INFO -         Start Nanny at: 'tcp://172.30.9.50:41620'
distributed.nanny - INFO -         Start Nanny at: 'tcp://172.30.9.50:33602'
distributed.nanny - INFO -         Start Nanny at: 'tcp://172.30.9.50:45749'
distributed.nanny - INFO -         Start Nanny at: 'tcp://172.30.9.50:42639'
distributed.nanny - INFO -         Start Nanny at: 'tcp://172.30.9.50:34670'
distributed.nanny - INFO -         Start Nanny at: 'tcp://172.30.9.50:37429'
distributed.nanny - INFO -         Start Nanny at: 'tcp://172.30.9.50:44202'
distributed.nanny - INFO -         Start Nanny at: 'tcp://172.30.9.50:32914'
distributed.nanny - INFO -         Start Nanny at: 'tcp://172.30.9.50:38402'
distributed.nanny - INFO -         Start Nanny at: 'tcp://172.30.9.50:37501'
distributed.nanny - INFO -         Start Nanny at: 'tcp://172.30.9.50:38324'
distributed.nanny - INFO -         Start Nanny at: 'tcp://172.30.9.50:38434'
distributed.nanny - INFO -         Start Nanny at: 'tcp://172.30.9.50:45609'
distributed.nanny - INFO -         Start Nanny at: 'tcp://172.30.9.50:34284'
/scratch/cnt0024/hmg2840/albert7a/anaconda3/lib/python3.7/site-packages/distributed/utils.py:136: RuntimeWarning: Couldn't detect a suitable IP address for reaching '8.8.8.8', defaulting to '127.0.0.1': [Errno 101] Network is unreachable
  RuntimeWarning,
distributed.diskutils - INFO - Found stale lock file and directory '/scratch/cnt0024/hmg2840/albert7a/daskjobqueue/worker-3swg3mcp', purging
distributed.diskutils - INFO - Found stale lock file and directory '/scratch/cnt0024/hmg2840/albert7a/daskjobqueue/worker-reytbwh7', purging
distributed.diskutils - INFO - Found stale lock file and directory '/scratch/cnt0024/hmg2840/albert7a/daskjobqueue/worker-0vtrkpal', purging
distributed.diskutils - INFO - Found stale lock file and directory '/scratch/cnt0024/hmg2840/albert7a/daskjobqueue/worker-29gxiq4z', purging
distributed.diskutils - INFO - Found stale lock file and directory '/scratch/cnt0024/hmg2840/albert7a/daskjobqueue/worker-pye7vqqj', purging
distributed.diskutils - INFO - Found stale lock file and directory '/scratch/cnt0024/hmg2840/albert7a/daskjobqueue/worker-15w7jlzw', purging
distributed.diskutils - INFO - Found stale lock file and directory '/scratch/cnt0024/hmg2840/albert7a/daskjobqueue/worker-dykvv6cb', purging
distributed.diskutils - INFO - Found stale lock file and directory '/scratch/cnt0024/hmg2840/albert7a/daskjobqueue/worker-rmdm943s', purging
distributed.diskutils - INFO - Found stale lock file and directory '/scratch/cnt0024/hmg2840/albert7a/daskjobqueue/worker-tculcw8x', purging
distributed.diskutils - INFO - Found stale lock file and directory '/scratch/cnt0024/hmg2840/albert7a/daskjobqueue/worker-n9gw46u6', purging
distributed.diskutils - INFO - Found stale lock file and directory '/scratch/cnt0024/hmg2840/albert7a/daskjobqueue/worker-w9v3mbr2', purging
distributed.diskutils - INFO - Found stale lock file and directory '/scratch/cnt0024/hmg2840/albert7a/daskjobqueue/worker-tdfvne0x', purging
distributed.diskutils - INFO - Found stale lock file and directory '/scratch/cnt0024/hmg2840/albert7a/daskjobqueue/worker-ujywmmrw', purging
distributed.diskutils - INFO - Found stale lock file and directory '/scratch/cnt0024/hmg2840/albert7a/daskjobqueue/worker-pejcuy76', purging
distributed.diskutils - INFO - Found stale lock file and directory '/scratch/cnt0024/hmg2840/albert7a/daskjobqueue/worker-rc9ii9un', purging
distributed.diskutils - INFO - Found stale lock file and directory '/scratch/cnt0024/hmg2840/albert7a/daskjobqueue/worker-8ahnafhn', purging
distributed.diskutils - INFO - Found stale lock file and directory '/scratch/cnt0024/hmg2840/albert7a/daskjobqueue/worker-h7yif9vm', purging
distributed.diskutils - INFO - Found stale lock file and directory '/scratch/cnt0024/hmg2840/albert7a/daskjobqueue/worker-xl4vwpji', purging
distributed.diskutils - INFO - Found stale lock file and directory '/scratch/cnt0024/hmg2840/albert7a/daskjobqueue/worker-07983mzz', purging
distributed.diskutils - INFO - Found stale lock file and directory '/scratch/cnt0024/hmg2840/albert7a/daskjobqueue/worker-aqpxcob_', purging
distributed.diskutils - INFO - Found stale lock file and directory '/scratch/cnt0024/hmg2840/albert7a/daskjobqueue/worker-y568hlf6', purging
distributed.diskutils - INFO - Found stale lock file and directory '/scratch/cnt0024/hmg2840/albert7a/daskjobqueue/worker-asecsnzg', purging
distributed.diskutils - INFO - Found stale lock file and directory '/scratch/cnt0024/hmg2840/albert7a/daskjobqueue/worker-wdelrpeh', purging
distributed.diskutils - INFO - Found stale lock file and directory '/scratch/cnt0024/hmg2840/albert7a/daskjobqueue/worker-9b80a6dh', purging
distributed.diskutils - INFO - Found stale lock file and directory '/scratch/cnt0024/hmg2840/albert7a/daskjobqueue/worker-mdmg_rie', purging
distributed.diskutils - INFO - Found stale lock file and directory '/scratch/cnt0024/hmg2840/albert7a/daskjobqueue/worker-rgyw3t9i', purging
distributed.diskutils - INFO - Found stale lock file and directory '/scratch/cnt0024/hmg2840/albert7a/daskjobqueue/worker-pkrh5zfw', purging
distributed.diskutils - INFO - Found stale lock file and directory '/scratch/cnt0024/hmg2840/albert7a/daskjobqueue/worker-2710x8sw', purging
distributed.diskutils - INFO - Found stale lock file and directory '/scratch/cnt0024/hmg2840/albert7a/daskjobqueue/worker-h3b8xc3s', purging
distributed.diskutils - INFO - Found stale lock file and directory '/scratch/cnt0024/hmg2840/albert7a/daskjobqueue/worker-ha0yw2k5', purging
distributed.diskutils - INFO - Found stale lock file and directory '/scratch/cnt0024/hmg2840/albert7a/daskjobqueue/worker-q99mwuph', purging
distributed.diskutils - INFO - Found stale lock file and directory '/scratch/cnt0024/hmg2840/albert7a/daskjobqueue/worker-8gtw22wq', purging
distributed.diskutils - INFO - Found stale lock file and directory '/scratch/cnt0024/hmg2840/albert7a/daskjobqueue/worker-oz3e0se_', purging
distributed.diskutils - INFO - Found stale lock file and directory '/scratch/cnt0024/hmg2840/albert7a/daskjobqueue/worker-lp30a2qc', purging
distributed.diskutils - INFO - Found stale lock file and directory '/scratch/cnt0024/hmg2840/albert7a/daskjobqueue/worker-yj6eaus0', purging
distributed.diskutils - INFO - Found stale lock file and directory '/scratch/cnt0024/hmg2840/albert7a/daskjobqueue/worker-iw441c_h', purging
distributed.diskutils - INFO - Found stale lock file and directory '/scratch/cnt0024/hmg2840/albert7a/daskjobqueue/worker-fal5r_cc', purging
distributed.diskutils - INFO - Found stale lock file and directory '/scratch/cnt0024/hmg2840/albert7a/daskjobqueue/worker-6j6o1601', purging
distributed.diskutils - INFO - Found stale lock file and directory '/scratch/cnt0024/hmg2840/albert7a/daskjobqueue/worker-1w87_duk', purging
distributed.diskutils - INFO - Found stale lock file and directory '/scratch/cnt0024/hmg2840/albert7a/daskjobqueue/worker-yd8adqob', purging
distributed.diskutils - INFO - Found stale lock file and directory '/scratch/cnt0024/hmg2840/albert7a/daskjobqueue/worker-7nha_3hm', purging
distributed.diskutils - INFO - Found stale lock file and directory '/scratch/cnt0024/hmg2840/albert7a/daskjobqueue/worker-akhju6_i', purging
distributed.diskutils - INFO - Found stale lock file and directory '/scratch/cnt0024/hmg2840/albert7a/daskjobqueue/worker-5pgh562p', purging
distributed.diskutils - INFO - Found stale lock file and directory '/scratch/cnt0024/hmg2840/albert7a/daskjobqueue/worker-9278e3lm', purging
distributed.diskutils - INFO - Found stale lock file and directory '/scratch/cnt0024/hmg2840/albert7a/daskjobqueue/worker-gpjt_wy8', purging
distributed.diskutils - INFO - Found stale lock file and directory '/scratch/cnt0024/hmg2840/albert7a/daskjobqueue/worker-_xveb9u5', purging
distributed.diskutils - INFO - Found stale lock file and directory '/scratch/cnt0024/hmg2840/albert7a/daskjobqueue/worker-oi5we4jx', purging
distributed.diskutils - INFO - Found stale lock file and directory '/scratch/cnt0024/hmg2840/albert7a/daskjobqueue/worker-_ckye_fr', purging
distributed.diskutils - INFO - Found stale lock file and directory '/scratch/cnt0024/hmg2840/albert7a/daskjobqueue/worker-1nibvcji', purging
distributed.diskutils - INFO - Found stale lock file and directory '/scratch/cnt0024/hmg2840/albert7a/daskjobqueue/worker-idd19xie', purging
distributed.diskutils - INFO - Found stale lock file and directory '/scratch/cnt0024/hmg2840/albert7a/daskjobqueue/worker-kc0lkndm', purging
distributed.diskutils - INFO - Found stale lock file and directory '/scratch/cnt0024/hmg2840/albert7a/daskjobqueue/worker-ac4hrfne', purging
distributed.diskutils - INFO - Found stale lock file and directory '/scratch/cnt0024/hmg2840/albert7a/daskjobqueue/worker-nllgu868', purging
distributed.diskutils - INFO - Found stale lock file and directory '/scratch/cnt0024/hmg2840/albert7a/daskjobqueue/worker-3cjgrdtp', purging
distributed.diskutils - INFO - Found stale lock file and directory '/scratch/cnt0024/hmg2840/albert7a/daskjobqueue/worker-obtoucnt', purging
distributed.diskutils - INFO - Found stale lock file and directory '/scratch/cnt0024/hmg2840/albert7a/daskjobqueue/worker-8ljtimvv', purging
distributed.nanny - INFO - Closing Nanny at 'tcp://172.30.9.50:41169'
distributed.nanny - INFO - Closing Nanny at 'tcp://172.30.9.50:41812'
distributed.nanny - INFO - Closing Nanny at 'tcp://172.30.9.50:45683'
distributed.nanny - INFO - Closing Nanny at 'tcp://172.30.9.50:33722'
distributed.nanny - INFO - Closing Nanny at 'tcp://172.30.9.50:37919'
distributed.nanny - INFO - Closing Nanny at 'tcp://172.30.9.50:45587'
distributed.nanny - INFO - Closing Nanny at 'tcp://172.30.9.50:44563'
distributed.nanny - INFO - Closing Nanny at 'tcp://172.30.9.50:36681'
distributed.nanny - INFO - Closing Nanny at 'tcp://172.30.9.50:45443'
distributed.nanny - INFO - Closing Nanny at 'tcp://172.30.9.50:36116'
distributed.nanny - INFO - Closing Nanny at 'tcp://172.30.9.50:35951'
distributed.nanny - INFO - Closing Nanny at 'tcp://172.30.9.50:34834'
distributed.nanny - INFO - Closing Nanny at 'tcp://172.30.9.50:35488'
distributed.nanny - INFO - Closing Nanny at 'tcp://172.30.9.50:34969'
distributed.nanny - INFO - Closing Nanny at 'tcp://172.30.9.50:41620'
distributed.nanny - INFO - Closing Nanny at 'tcp://172.30.9.50:33602'
distributed.nanny - INFO - Closing Nanny at 'tcp://172.30.9.50:45749'
distributed.nanny - INFO - Closing Nanny at 'tcp://172.30.9.50:42639'
distributed.nanny - INFO - Closing Nanny at 'tcp://172.30.9.50:34670'
distributed.nanny - INFO - Closing Nanny at 'tcp://172.30.9.50:37429'
distributed.nanny - INFO - Closing Nanny at 'tcp://172.30.9.50:44202'
distributed.nanny - INFO - Closing Nanny at 'tcp://172.30.9.50:32914'
distributed.nanny - INFO - Closing Nanny at 'tcp://172.30.9.50:38402'
distributed.nanny - INFO - Closing Nanny at 'tcp://172.30.9.50:37501'
distributed.nanny - INFO - Closing Nanny at 'tcp://172.30.9.50:38324'
distributed.nanny - INFO - Closing Nanny at 'tcp://172.30.9.50:38434'
distributed.nanny - INFO - Closing Nanny at 'tcp://172.30.9.50:45609'
distributed.nanny - INFO - Closing Nanny at 'tcp://172.30.9.50:34284'
/scratch/cnt0024/hmg2840/albert7a/anaconda3/lib/python3.7/site-packages/distributed/utils.py:136: RuntimeWarning: Couldn't detect a suitable IP address for reaching '8.8.8.8', defaulting to '127.0.0.1': [Errno 101] Network is unreachable
  RuntimeWarning,
distributed.worker - INFO - Stopping worker
/scratch/cnt0024/hmg2840/albert7a/anaconda3/lib/python3.7/site-packages/distributed/utils.py:136: RuntimeWarning: Couldn't detect a suitable IP address for reaching '8.8.8.8', defaulting to '127.0.0.1': [Errno 101] Network is unreachable
  RuntimeWarning,
distributed.worker - INFO - Stopping worker
/scratch/cnt0024/hmg2840/albert7a/anaconda3/lib/python3.7/site-packages/distributed/utils.py:136: RuntimeWarning: Couldn't detect a suitable IP address for reaching '8.8.8.8', defaulting to '127.0.0.1': [Errno 101] Network is unreachable
  RuntimeWarning,
distributed.worker - INFO - Stopping worker
/scratch/cnt0024/hmg2840/albert7a/anaconda3/lib/python3.7/site-packages/distributed/utils.py:136: RuntimeWarning: Couldn't detect a suitable IP address for reaching '8.8.8.8', defaulting to '127.0.0.1': [Errno 101] Network is unreachable
  RuntimeWarning,
distributed.worker - INFO - Stopping worker
/scratch/cnt0024/hmg2840/albert7a/anaconda3/lib/python3.7/site-packages/distributed/utils.py:136: RuntimeWarning: Couldn't detect a suitable IP address for reaching '8.8.8.8', defaulting to '127.0.0.1': [Errno 101] Network is unreachable
  RuntimeWarning,
distributed.worker - INFO - Stopping worker
/scratch/cnt0024/hmg2840/albert7a/anaconda3/lib/python3.7/site-packages/distributed/utils.py:136: RuntimeWarning: Couldn't detect a suitable IP address for reaching '8.8.8.8', defaulting to '127.0.0.1': [Errno 101] Network is unreachable
  RuntimeWarning,
distributed.worker - INFO - Stopping worker
distributed.nanny - ERROR - Failed to start worker
Traceback (most recent call last):
  File "/scratch/cnt0024/hmg2840/albert7a/anaconda3/lib/python3.7/site-packages/distributed/nanny.py", line 674, in run
    yield worker._start(*worker_start_args)
  File "/scratch/cnt0024/hmg2840/albert7a/anaconda3/lib/python3.7/site-packages/tornado/gen.py", line 729, in run
    value = future.result()
  File "/scratch/cnt0024/hmg2840/albert7a/anaconda3/lib/python3.7/site-packages/tornado/gen.py", line 209, in wrapper
    yielded = next(result)
  File "/scratch/cnt0024/hmg2840/albert7a/anaconda3/lib/python3.7/site-packages/distributed/worker.py", line 896, in _start
    assert self.status is None
AssertionError
distributed.nanny - ERROR - Failed to start worker
Traceback (most recent call last):
  File "/scratch/cnt0024/hmg2840/albert7a/anaconda3/lib/python3.7/site-packages/distributed/nanny.py", line 674, in run
    yield worker._start(*worker_start_args)
  File "/scratch/cnt0024/hmg2840/albert7a/anaconda3/lib/python3.7/site-packages/tornado/gen.py", line 729, in run
    value = future.result()
  File "/scratch/cnt0024/hmg2840/albert7a/anaconda3/lib/python3.7/site-packages/tornado/gen.py", line 209, in wrapper
    yielded = next(result)
  File "/scratch/cnt0024/hmg2840/albert7a/anaconda3/lib/python3.7/site-packages/distributed/worker.py", line 896, in _start
    assert self.status is None
AssertionError
/scratch/cnt0024/hmg2840/albert7a/anaconda3/lib/python3.7/site-packages/distributed/utils.py:136: RuntimeWarning: Couldn't detect a suitable IP address for reaching '8.8.8.8', defaulting to '127.0.0.1': [Errno 101] Network is unreachable
  RuntimeWarning,
distributed.worker - INFO -       Start worker at:    tcp://172.30.9.50:40545
/scratch/cnt0024/hmg2840/albert7a/anaconda3/lib/python3.7/site-packages/distributed/utils.py:136: RuntimeWarning: Couldn't detect a suitable IP address for reaching '8.8.8.8', defaulting to '127.0.0.1': [Errno 101] Network is unreachable
  RuntimeWarning,
distributed.worker - INFO -       Start worker at:    tcp://172.30.9.50:43629
/scratch/cnt0024/hmg2840/albert7a/anaconda3/lib/python3.7/site-packages/distributed/utils.py:136: RuntimeWarning: Couldn't detect a suitable IP address for reaching '8.8.8.8', defaulting to '127.0.0.1': [Errno 101] Network is unreachable
  RuntimeWarning,
distributed.worker - INFO -       Start worker at:    tcp://172.30.9.50:37930
/scratch/cnt0024/hmg2840/albert7a/anaconda3/lib/python3.7/site-packages/distributed/utils.py:136: RuntimeWarning: Couldn't detect a suitable IP address for reaching '8.8.8.8', defaulting to '127.0.0.1': [Errno 101] Network is unreachable
  RuntimeWarning,
distributed.worker - INFO -       Start worker at:    tcp://172.30.9.50:45593
distributed.worker - INFO -          Listening to:    tcp://172.30.9.50:40545
distributed.worker - INFO -          Listening to:    tcp://172.30.9.50:43629
/scratch/cnt0024/hmg2840/albert7a/anaconda3/lib/python3.7/site-packages/distributed/utils.py:136: RuntimeWarning: Couldn't detect a suitable IP address for reaching '8.8.8.8', defaulting to '127.0.0.1': [Errno 101] Network is unreachable
  RuntimeWarning,
distributed.worker - INFO -       Start worker at:    tcp://172.30.9.50:45408
distributed.worker - INFO -          Listening to:    tcp://172.30.9.50:37930
/scratch/cnt0024/hmg2840/albert7a/anaconda3/lib/python3.7/site-packages/distributed/utils.py:136: RuntimeWarning: Couldn't detect a suitable IP address for reaching '8.8.8.8', defaulting to '127.0.0.1': [Errno 101] Network is unreachable
  RuntimeWarning,
distributed.worker - INFO -       Start worker at:    tcp://172.30.9.50:36973
/scratch/cnt0024/hmg2840/albert7a/anaconda3/lib/python3.7/site-packages/distributed/utils.py:136: RuntimeWarning: Couldn't detect a suitable IP address for reaching '8.8.8.8', defaulting to '127.0.0.1': [Errno 101] Network is unreachable
  RuntimeWarning,
distributed.worker - INFO -       Start worker at:    tcp://172.30.9.50:37351
/scratch/cnt0024/hmg2840/albert7a/anaconda3/lib/python3.7/site-packages/distributed/utils.py:136: RuntimeWarning: Couldn't detect a suitable IP address for reaching '8.8.8.8', defaulting to '127.0.0.1': [Errno 101] Network is unreachable
  RuntimeWarning,
distributed.worker - INFO -       Start worker at:    tcp://172.30.9.50:40441
distributed.worker - INFO -          Listening to:    tcp://172.30.9.50:45593
/scratch/cnt0024/hmg2840/albert7a/anaconda3/lib/python3.7/site-packages/distributed/utils.py:136: RuntimeWarning: Couldn't detect a suitable IP address for reaching '8.8.8.8', defaulting to '127.0.0.1': [Errno 101] Network is unreachable
  RuntimeWarning,
distributed.worker - INFO -       Start worker at:    tcp://172.30.9.50:37274
distributed.worker - INFO -          dashboard at:          172.30.9.50:39764
distributed.worker - INFO -          Listening to:    tcp://172.30.9.50:36973
distributed.worker - INFO -          Listening to:    tcp://172.30.9.50:45408
distributed.worker - INFO -          dashboard at:          172.30.9.50:34875
distributed.worker - INFO -          dashboard at:          172.30.9.50:38474
distributed.worker - INFO -          Listening to:    tcp://172.30.9.50:37351
/scratch/cnt0024/hmg2840/albert7a/anaconda3/lib/python3.7/site-packages/distributed/utils.py:136: RuntimeWarning: Couldn't detect a suitable IP address for reaching '8.8.8.8', defaulting to '127.0.0.1': [Errno 101] Network is unreachable
  RuntimeWarning,
distributed.worker - INFO -       Start worker at:    tcp://172.30.9.50:44606
distributed.worker - INFO -          Listening to:    tcp://172.30.9.50:40441
distributed.worker - INFO - Waiting to connect to:   tcp://172.30.100.4:42246
distributed.worker - INFO -          dashboard at:          172.30.9.50:46421
distributed.worker - INFO -          Listening to:    tcp://172.30.9.50:37274
distributed.worker - INFO - Waiting to connect to:   tcp://172.30.100.4:42246
distributed.worker - INFO - Waiting to connect to:   tcp://172.30.100.4:42246
distributed.worker - INFO -          dashboard at:          172.30.9.50:45019
distributed.worker - INFO -          Listening to:    tcp://172.30.9.50:44606
distributed.worker - INFO - -------------------------------------------------
distributed.worker - INFO - Waiting to connect to:   tcp://172.30.100.4:42246
distributed.worker - INFO -          dashboard at:          172.30.9.50:46749
distributed.worker - INFO - -------------------------------------------------
distributed.worker - INFO -          dashboard at:          172.30.9.50:37923
distributed.worker - INFO - -------------------------------------------------
distributed.worker - INFO -          dashboard at:          172.30.9.50:39454
distributed.worker - INFO - Waiting to connect to:   tcp://172.30.100.4:42246
distributed.worker - INFO -          dashboard at:          172.30.9.50:45317
distributed.worker - INFO - -------------------------------------------------
distributed.worker - INFO - Waiting to connect to:   tcp://172.30.100.4:42246
distributed.worker - INFO -          dashboard at:          172.30.9.50:33872
distributed.worker - INFO - Waiting to connect to:   tcp://172.30.100.4:42246
distributed.worker - INFO - -------------------------------------------------
distributed.worker - INFO - Waiting to connect to:   tcp://172.30.100.4:42246
distributed.worker - INFO -               Threads:                          1
/scratch/cnt0024/hmg2840/albert7a/anaconda3/lib/python3.7/site-packages/distributed/utils.py:136: RuntimeWarning: Couldn't detect a suitable IP address for reaching '8.8.8.8', defaulting to '127.0.0.1': [Errno 101] Network is unreachable
  RuntimeWarning,
distributed.worker - INFO -       Start worker at:    tcp://172.30.9.50:44107
distributed.worker - INFO -               Threads:                          1
/scratch/cnt0024/hmg2840/albert7a/anaconda3/lib/python3.7/site-packages/distributed/utils.py:136: RuntimeWarning: Couldn't detect a suitable IP address for reaching '8.8.8.8', defaulting to '127.0.0.1': [Errno 101] Network is unreachable
  RuntimeWarning,
distributed.worker - INFO -       Start worker at:    tcp://172.30.9.50:38507
distributed.worker - INFO - -------------------------------------------------
distributed.worker - INFO - Waiting to connect to:   tcp://172.30.100.4:42246
distributed.worker - INFO -               Threads:                          1
distributed.worker - INFO - Waiting to connect to:   tcp://172.30.100.4:42246
distributed.worker - INFO - -------------------------------------------------
distributed.worker - INFO - -------------------------------------------------
distributed.worker - INFO -               Threads:                          1
distributed.worker - INFO -                Memory:                    4.29 GB
distributed.worker - INFO -                Memory:                    4.29 GB
distributed.worker - INFO -               Threads:                          1
distributed.worker - INFO -          Listening to:    tcp://172.30.9.50:44107
distributed.worker - INFO - -------------------------------------------------
distributed.worker - INFO -                Memory:                    4.29 GB
distributed.worker - INFO - -------------------------------------------------
distributed.worker - INFO -          Listening to:    tcp://172.30.9.50:38507
distributed.worker - INFO -       Local Directory: /scratch/cnt0024/hmg2840/albert7a/daskjobqueue/worker-kb68xohl
distributed.worker - INFO -                Memory:                    4.29 GB
distributed.worker - INFO -       Local Directory: /scratch/cnt0024/hmg2840/albert7a/daskjobqueue/worker-40105rm6
distributed.worker - INFO -               Threads:                          1
distributed.worker - INFO -                Memory:                    4.29 GB
distributed.worker - INFO -               Threads:                          1
distributed.worker - INFO -       Local Directory: /scratch/cnt0024/hmg2840/albert7a/daskjobqueue/worker-pboaoqv8
distributed.worker - INFO -               Threads:                          1
distributed.worker - INFO -       Local Directory: /scratch/cnt0024/hmg2840/albert7a/daskjobqueue/worker-y7cty437
distributed.worker - INFO -          dashboard at:          172.30.9.50:40268
distributed.worker - INFO -       Local Directory: /scratch/cnt0024/hmg2840/albert7a/daskjobqueue/worker-6dnrbfhd
distributed.worker - INFO -                Memory:                    4.29 GB
distributed.worker - INFO -               Threads:                          1
distributed.worker - INFO -               Threads:                          1
distributed.worker - INFO -                Memory:                    4.29 GB
distributed.worker - INFO -                Memory:                    4.29 GB
distributed.worker - INFO -       Local Directory: /scratch/cnt0024/hmg2840/albert7a/daskjobqueue/worker-6_ld9uf8
distributed.worker - INFO - Waiting to connect to:   tcp://172.30.100.4:42246
distributed.worker - INFO -                Memory:                    4.29 GB
distributed.worker - INFO -       Local Directory: /scratch/cnt0024/hmg2840/albert7a/daskjobqueue/worker-ojhlncku
distributed.worker - INFO -                Memory:                    4.29 GB
distributed.worker - INFO -          dashboard at:          172.30.9.50:40616
distributed.worker - INFO -       Local Directory: /scratch/cnt0024/hmg2840/albert7a/daskjobqueue/worker-90g35hvy
distributed.worker - INFO - -------------------------------------------------
distributed.worker - INFO - -------------------------------------------------
distributed.worker - INFO -       Local Directory: /scratch/cnt0024/hmg2840/albert7a/daskjobqueue/worker-aqjtzjbo
distributed.worker - INFO -       Local Directory: /scratch/cnt0024/hmg2840/albert7a/daskjobqueue/worker-_pzp6vq4
distributed.worker - INFO - -------------------------------------------------
distributed.worker - INFO - -------------------------------------------------
distributed.worker - INFO - -------------------------------------------------
distributed.worker - INFO - -------------------------------------------------
distributed.worker - INFO - Waiting to connect to:   tcp://172.30.100.4:42246
distributed.worker - INFO - -------------------------------------------------
distributed.worker - INFO - -------------------------------------------------
distributed.worker - INFO - -------------------------------------------------
distributed.worker - INFO - -------------------------------------------------
distributed.worker - INFO - -------------------------------------------------
distributed.worker - INFO - -------------------------------------------------
distributed.worker - INFO -               Threads:                          1
distributed.worker - INFO -                Memory:                    4.29 GB
distributed.worker - INFO -       Local Directory: /scratch/cnt0024/hmg2840/albert7a/daskjobqueue/worker-g62cibyo
distributed.worker - INFO -               Threads:                          1
distributed.worker - INFO -                Memory:                    4.29 GB
distributed.nanny - ERROR - Failed to start worker
Traceback (most recent call last):
  File "/scratch/cnt0024/hmg2840/albert7a/anaconda3/lib/python3.7/site-packages/distributed/nanny.py", line 674, in run
    yield worker._start(*worker_start_args)
  File "/scratch/cnt0024/hmg2840/albert7a/anaconda3/lib/python3.7/site-packages/tornado/gen.py", line 729, in run
    value = future.result()
  File "/scratch/cnt0024/hmg2840/albert7a/anaconda3/lib/python3.7/site-packages/tornado/gen.py", line 209, in wrapper
    yielded = next(result)
  File "/scratch/cnt0024/hmg2840/albert7a/anaconda3/lib/python3.7/site-packages/distributed/worker.py", line 896, in _start
    assert self.status is None
AssertionError
distributed.worker - INFO -       Local Directory: /scratch/cnt0024/hmg2840/albert7a/daskjobqueue/worker-5o344vj9
distributed.worker - INFO - Stopping worker at tcp://172.30.9.50:37930
distributed.worker - INFO - -------------------------------------------------
distributed.worker - INFO - Stopping worker at tcp://172.30.9.50:40545
distributed.worker - INFO - Stopping worker at tcp://172.30.9.50:43629
distributed.worker - INFO - Stopping worker at tcp://172.30.9.50:45593
distributed.worker - INFO - Stopping worker at tcp://172.30.9.50:45408
distributed.worker - INFO - Stopping worker at tcp://172.30.9.50:36973
distributed.worker - INFO - Stopping worker at tcp://172.30.9.50:40441
distributed.worker - INFO - Stopping worker at tcp://172.30.9.50:44606
distributed.worker - INFO - -------------------------------------------------
distributed.worker - INFO - Stopping worker at tcp://172.30.9.50:37274
distributed.worker - INFO - Stopping worker at tcp://172.30.9.50:37351
distributed.worker - INFO - Stopping worker at tcp://172.30.9.50:44107
distributed.worker - INFO - Stopping worker at tcp://172.30.9.50:38507
/scratch/cnt0024/hmg2840/albert7a/anaconda3/lib/python3.7/site-packages/distributed/utils.py:136: RuntimeWarning: Couldn't detect a suitable IP address for reaching '8.8.8.8', defaulting to '127.0.0.1': [Errno 101] Network is unreachable
  RuntimeWarning,
distributed.worker - INFO -       Start worker at:    tcp://172.30.9.50:43195
distributed.nanny - ERROR - Failed to start worker
Traceback (most recent call last):
  File "/scratch/cnt0024/hmg2840/albert7a/anaconda3/lib/python3.7/site-packages/distributed/nanny.py", line 674, in run
    yield worker._start(*worker_start_args)
  File "/scratch/cnt0024/hmg2840/albert7a/anaconda3/lib/python3.7/site-packages/tornado/gen.py", line 729, in run
    value = future.result()
  File "/scratch/cnt0024/hmg2840/albert7a/anaconda3/lib/python3.7/site-packages/tornado/gen.py", line 209, in wrapper
    yielded = next(result)
  File "/scratch/cnt0024/hmg2840/albert7a/anaconda3/lib/python3.7/site-packages/distributed/worker.py", line 896, in _start
    assert self.status is None
AssertionError
distributed.worker - INFO -          Listening to:    tcp://172.30.9.50:43195
distributed.worker - INFO -          dashboard at:          172.30.9.50:35861
distributed.worker - INFO - Waiting to connect to:   tcp://172.30.100.4:42246
distributed.worker - INFO - -------------------------------------------------
distributed.worker - INFO -               Threads:                          1
distributed.worker - INFO -                Memory:                    4.29 GB
distributed.worker - INFO -       Local Directory: /scratch/cnt0024/hmg2840/albert7a/daskjobqueue/worker-wc__7z2o
distributed.worker - INFO - -------------------------------------------------
/scratch/cnt0024/hmg2840/albert7a/anaconda3/lib/python3.7/site-packages/distributed/utils.py:136: RuntimeWarning: Couldn't detect a suitable IP address for reaching '8.8.8.8', defaulting to '127.0.0.1': [Errno 101] Network is unreachable
  RuntimeWarning,
distributed.worker - INFO -       Start worker at:    tcp://172.30.9.50:45810
distributed.worker - INFO -          Listening to:    tcp://172.30.9.50:45810
distributed.worker - INFO -          dashboard at:          172.30.9.50:41193
distributed.worker - INFO - Waiting to connect to:   tcp://172.30.100.4:42246
distributed.worker - INFO - -------------------------------------------------
distributed.worker - INFO -               Threads:                          1
distributed.worker - INFO -                Memory:                    4.29 GB
distributed.worker - INFO -       Local Directory: /scratch/cnt0024/hmg2840/albert7a/daskjobqueue/worker-8ayb2ppf
distributed.worker - INFO - -------------------------------------------------
distributed.worker - INFO - Stopping worker at tcp://172.30.9.50:43195
/scratch/cnt0024/hmg2840/albert7a/anaconda3/lib/python3.7/site-packages/distributed/utils.py:136: RuntimeWarning: Couldn't detect a suitable IP address for reaching '8.8.8.8', defaulting to '127.0.0.1': [Errno 101] Network is unreachable
  RuntimeWarning,
distributed.worker - INFO -       Start worker at:    tcp://172.30.9.50:33768
distributed.worker - INFO -          Listening to:    tcp://172.30.9.50:33768
distributed.worker - INFO -          dashboard at:          172.30.9.50:42914
distributed.worker - INFO - Stopping worker at tcp://172.30.9.50:45810
distributed.worker - INFO - Waiting to connect to:   tcp://172.30.100.4:42246
distributed.worker - INFO - -------------------------------------------------
distributed.worker - INFO -               Threads:                          1
distributed.worker - INFO -                Memory:                    4.29 GB
distributed.worker - INFO -       Local Directory: /scratch/cnt0024/hmg2840/albert7a/daskjobqueue/worker-zhkgk24j
/scratch/cnt0024/hmg2840/albert7a/anaconda3/lib/python3.7/site-packages/distributed/utils.py:136: RuntimeWarning: Couldn't detect a suitable IP address for reaching '8.8.8.8', defaulting to '127.0.0.1': [Errno 101] Network is unreachable
  RuntimeWarning,
distributed.worker - INFO -       Start worker at:    tcp://172.30.9.50:42177
distributed.worker - INFO -          Listening to:    tcp://172.30.9.50:42177
distributed.worker - INFO - -------------------------------------------------
distributed.worker - INFO -          dashboard at:          172.30.9.50:40439
distributed.worker - INFO - Waiting to connect to:   tcp://172.30.100.4:42246
distributed.worker - INFO - -------------------------------------------------
distributed.worker - INFO -               Threads:                          1
distributed.worker - INFO -                Memory:                    4.29 GB
distributed.worker - INFO -       Local Directory: /scratch/cnt0024/hmg2840/albert7a/daskjobqueue/worker-wi6h1z_i
/scratch/cnt0024/hmg2840/albert7a/anaconda3/lib/python3.7/site-packages/distributed/utils.py:136: RuntimeWarning: Couldn't detect a suitable IP address for reaching '8.8.8.8', defaulting to '127.0.0.1': [Errno 101] Network is unreachable
  RuntimeWarning,
distributed.worker - INFO -       Start worker at:    tcp://172.30.9.50:46126
distributed.worker - INFO -       Start worker at:    tcp://172.30.9.50:37817
distributed.worker - INFO - -------------------------------------------------
distributed.worker - INFO - Stopping worker at tcp://172.30.9.50:33768
distributed.nanny - ERROR - Failed to start worker
Traceback (most recent call last):
  File "/scratch/cnt0024/hmg2840/albert7a/anaconda3/lib/python3.7/site-packages/distributed/nanny.py", line 674, in run
    yield worker._start(*worker_start_args)
  File "/scratch/cnt0024/hmg2840/albert7a/anaconda3/lib/python3.7/site-packages/tornado/gen.py", line 729, in run
    value = future.result()
  File "/scratch/cnt0024/hmg2840/albert7a/anaconda3/lib/python3.7/site-packages/tornado/gen.py", line 209, in wrapper
    yielded = next(result)
  File "/scratch/cnt0024/hmg2840/albert7a/anaconda3/lib/python3.7/site-packages/distributed/worker.py", line 896, in _start
    assert self.status is None
AssertionError
/scratch/cnt0024/hmg2840/albert7a/anaconda3/lib/python3.7/site-packages/distributed/utils.py:136: RuntimeWarning: Couldn't detect a suitable IP address for reaching '8.8.8.8', defaulting to '127.0.0.1': [Errno 101] Network is unreachable
  RuntimeWarning,
distributed.worker - INFO -       Start worker at:    tcp://172.30.9.50:33068
distributed.worker - INFO -          Listening to:    tcp://172.30.9.50:37817
distributed.worker - INFO -          Listening to:    tcp://172.30.9.50:46126
/scratch/cnt0024/hmg2840/albert7a/anaconda3/lib/python3.7/site-packages/distributed/utils.py:136: RuntimeWarning: Couldn't detect a suitable IP address for reaching '8.8.8.8', defaulting to '127.0.0.1': [Errno 101] Network is unreachable
  RuntimeWarning,
distributed.worker - INFO -       Start worker at:    tcp://172.30.9.50:34301
distributed.nanny - ERROR - Failed to start worker
Traceback (most recent call last):
  File "/scratch/cnt0024/hmg2840/albert7a/anaconda3/lib/python3.7/site-packages/distributed/nanny.py", line 674, in run
    yield worker._start(*worker_start_args)
  File "/scratch/cnt0024/hmg2840/albert7a/anaconda3/lib/python3.7/site-packages/tornado/gen.py", line 729, in run
    value = future.result()
  File "/scratch/cnt0024/hmg2840/albert7a/anaconda3/lib/python3.7/site-packages/tornado/gen.py", line 209, in wrapper
    yielded = next(result)
  File "/scratch/cnt0024/hmg2840/albert7a/anaconda3/lib/python3.7/site-packages/distributed/worker.py", line 896, in _start
    assert self.status is None
AssertionError
distributed.worker - INFO -          dashboard at:          172.30.9.50:39474
distributed.worker - INFO -          Listening to:    tcp://172.30.9.50:33068
distributed.worker - INFO -          Listening to:    tcp://172.30.9.50:34301
/scratch/cnt0024/hmg2840/albert7a/anaconda3/lib/python3.7/site-packages/distributed/utils.py:136: RuntimeWarning: Couldn't detect a suitable IP address for reaching '8.8.8.8', defaulting to '127.0.0.1': [Errno 101] Network is unreachable
  RuntimeWarning,
distributed.worker - INFO -       Start worker at:    tcp://172.30.9.50:42981
distributed.worker - INFO -          dashboard at:          172.30.9.50:35344
distributed.worker - INFO - Waiting to connect to:   tcp://172.30.100.4:42246
distributed.worker - INFO -          dashboard at:          172.30.9.50:40353
distributed.worker - INFO -          dashboard at:          172.30.9.50:37378
distributed.worker - INFO -          Listening to:    tcp://172.30.9.50:42981
distributed.worker - INFO - Waiting to connect to:   tcp://172.30.100.4:42246
distributed.worker - INFO - -------------------------------------------------
distributed.worker - INFO - Waiting to connect to:   tcp://172.30.100.4:42246
distributed.worker - INFO - Waiting to connect to:   tcp://172.30.100.4:42246
distributed.worker - INFO - -------------------------------------------------
distributed.worker - INFO -          dashboard at:          172.30.9.50:42982
distributed.worker - INFO - -------------------------------------------------
distributed.worker - INFO - -------------------------------------------------
distributed.worker - INFO - Waiting to connect to:   tcp://172.30.100.4:42246
distributed.worker - INFO -               Threads:                          1
distributed.worker - INFO - -------------------------------------------------
distributed.worker - INFO -               Threads:                          1
distributed.worker - INFO -                Memory:                    4.29 GB
distributed.worker - INFO -               Threads:                          1
distributed.worker - INFO -                Memory:                    4.29 GB
distributed.worker - INFO -                Memory:                    4.29 GB
distributed.worker - INFO -       Local Directory: /scratch/cnt0024/hmg2840/albert7a/daskjobqueue/worker-7apas9f1
distributed.worker - INFO -       Local Directory: /scratch/cnt0024/hmg2840/albert7a/daskjobqueue/worker-ro3u9674
distributed.worker - INFO -               Threads:                          1
distributed.worker - INFO -               Threads:                          1
distributed.worker - INFO -       Local Directory: /scratch/cnt0024/hmg2840/albert7a/daskjobqueue/worker-q5lgel32
distributed.worker - INFO -                Memory:                    4.29 GB
distributed.worker - INFO -                Memory:                    4.29 GB
distributed.worker - INFO -       Local Directory: /scratch/cnt0024/hmg2840/albert7a/daskjobqueue/worker-5ae7h614
distributed.worker - INFO - Stopping worker at tcp://172.30.9.50:42177
distributed.worker - INFO -       Local Directory: /scratch/cnt0024/hmg2840/albert7a/daskjobqueue/worker-vm49w99s
distributed.worker - INFO - -------------------------------------------------
distributed.worker - INFO - -------------------------------------------------
distributed.worker - INFO - -------------------------------------------------
distributed.worker - INFO - -------------------------------------------------
distributed.worker - INFO - -------------------------------------------------
distributed.worker - INFO - Stopping worker at tcp://172.30.9.50:33068
distributed.worker - INFO - Stopping worker at tcp://172.30.9.50:37817
distributed.worker - INFO - Stopping worker at tcp://172.30.9.50:34301
distributed.worker - INFO - Stopping worker at tcp://172.30.9.50:42981
distributed.worker - INFO - Stopping worker at tcp://172.30.9.50:46126
/scratch/cnt0024/hmg2840/albert7a/anaconda3/lib/python3.7/site-packages/distributed/utils.py:136: RuntimeWarning: Couldn't detect a suitable IP address for reaching '8.8.8.8', defaulting to '127.0.0.1': [Errno 101] Network is unreachable
  RuntimeWarning,
distributed.worker - INFO -       Start worker at:    tcp://172.30.9.50:34098
distributed.worker - INFO -          Listening to:    tcp://172.30.9.50:34098
distributed.worker - INFO -          dashboard at:          172.30.9.50:44984
distributed.worker - INFO - Waiting to connect to:   tcp://172.30.100.4:42246
distributed.worker - INFO - -------------------------------------------------
distributed.worker - INFO -               Threads:                          1
distributed.worker - INFO -                Memory:                    4.29 GB
distributed.worker - INFO -       Local Directory: /scratch/cnt0024/hmg2840/albert7a/daskjobqueue/worker-qv6v44g7
distributed.worker - INFO - -------------------------------------------------
distributed.worker - INFO - Stopping worker at tcp://172.30.9.50:34098
distributed.nanny - ERROR - Timed out connecting Nanny '<Nanny: None, threads: 1>' to scheduler 'tcp://172.30.100.4:42246'
Traceback (most recent call last):
  File "/scratch/cnt0024/hmg2840/albert7a/anaconda3/lib/python3.7/site-packages/distributed/nanny.py", line 303, in instantiate
    timedelta(seconds=self.death_timeout), self.process.start()
  File "/scratch/cnt0024/hmg2840/albert7a/anaconda3/lib/python3.7/site-packages/tornado/gen.py", line 729, in run
    value = future.result()
tornado.util.TimeoutError: Timeout
distributed.nanny - ERROR - Timed out connecting Nanny '<Nanny: None, threads: 1>' to scheduler 'tcp://172.30.100.4:42246'
Traceback (most recent call last):
  File "/scratch/cnt0024/hmg2840/albert7a/anaconda3/lib/python3.7/site-packages/distributed/nanny.py", line 303, in instantiate
    timedelta(seconds=self.death_timeout), self.process.start()
  File "/scratch/cnt0024/hmg2840/albert7a/anaconda3/lib/python3.7/site-packages/tornado/gen.py", line 729, in run
    value = future.result()
tornado.util.TimeoutError: Timeout
distributed.nanny - ERROR - Timed out connecting Nanny '<Nanny: None, threads: 1>' to scheduler 'tcp://172.30.100.4:42246'
Traceback (most recent call last):
  File "/scratch/cnt0024/hmg2840/albert7a/anaconda3/lib/python3.7/site-packages/distributed/nanny.py", line 303, in instantiate
    timedelta(seconds=self.death_timeout), self.process.start()
  File "/scratch/cnt0024/hmg2840/albert7a/anaconda3/lib/python3.7/site-packages/tornado/gen.py", line 729, in run
    value = future.result()
tornado.util.TimeoutError: Timeout
distributed.nanny - ERROR - Timed out connecting Nanny '<Nanny: None, threads: 1>' to scheduler 'tcp://172.30.100.4:42246'
Traceback (most recent call last):
  File "/scratch/cnt0024/hmg2840/albert7a/anaconda3/lib/python3.7/site-packages/distributed/nanny.py", line 303, in instantiate
    timedelta(seconds=self.death_timeout), self.process.start()
  File "/scratch/cnt0024/hmg2840/albert7a/anaconda3/lib/python3.7/site-packages/tornado/gen.py", line 729, in run
    value = future.result()
tornado.util.TimeoutError: Timeout
distributed.nanny - ERROR - Timed out connecting Nanny '<Nanny: None, threads: 1>' to scheduler 'tcp://172.30.100.4:42246'
Traceback (most recent call last):
  File "/scratch/cnt0024/hmg2840/albert7a/anaconda3/lib/python3.7/site-packages/distributed/nanny.py", line 303, in instantiate
    timedelta(seconds=self.death_timeout), self.process.start()
  File "/scratch/cnt0024/hmg2840/albert7a/anaconda3/lib/python3.7/site-packages/tornado/gen.py", line 729, in run
    value = future.result()
tornado.util.TimeoutError: Timeout
distributed.nanny - ERROR - Timed out connecting Nanny '<Nanny: None, threads: 1>' to scheduler 'tcp://172.30.100.4:42246'
Traceback (most recent call last):
  File "/scratch/cnt0024/hmg2840/albert7a/anaconda3/lib/python3.7/site-packages/distributed/nanny.py", line 303, in instantiate
    timedelta(seconds=self.death_timeout), self.process.start()
  File "/scratch/cnt0024/hmg2840/albert7a/anaconda3/lib/python3.7/site-packages/tornado/gen.py", line 729, in run
    value = future.result()
tornado.util.TimeoutError: Timeout
distributed.nanny - ERROR - Timed out connecting Nanny '<Nanny: None, threads: 1>' to scheduler 'tcp://172.30.100.4:42246'
Traceback (most recent call last):
  File "/scratch/cnt0024/hmg2840/albert7a/anaconda3/lib/python3.7/site-packages/distributed/nanny.py", line 303, in instantiate
    timedelta(seconds=self.death_timeout), self.process.start()
  File "/scratch/cnt0024/hmg2840/albert7a/anaconda3/lib/python3.7/site-packages/tornado/gen.py", line 729, in run
    value = future.result()
tornado.util.TimeoutError: Timeout
distributed.nanny - ERROR - Timed out connecting Nanny '<Nanny: None, threads: 1>' to scheduler 'tcp://172.30.100.4:42246'
Traceback (most recent call last):
  File "/scratch/cnt0024/hmg2840/albert7a/anaconda3/lib/python3.7/site-packages/distributed/nanny.py", line 303, in instantiate
    timedelta(seconds=self.death_timeout), self.process.start()
  File "/scratch/cnt0024/hmg2840/albert7a/anaconda3/lib/python3.7/site-packages/tornado/gen.py", line 729, in run
    value = future.result()
tornado.util.TimeoutError: Timeout
distributed.nanny - ERROR - Timed out connecting Nanny '<Nanny: None, threads: 1>' to scheduler 'tcp://172.30.100.4:42246'
Traceback (most recent call last):
  File "/scratch/cnt0024/hmg2840/albert7a/anaconda3/lib/python3.7/site-packages/distributed/nanny.py", line 303, in instantiate
    timedelta(seconds=self.death_timeout), self.process.start()
  File "/scratch/cnt0024/hmg2840/albert7a/anaconda3/lib/python3.7/site-packages/tornado/gen.py", line 729, in run
    value = future.result()
tornado.util.TimeoutError: Timeout
distributed.nanny - ERROR - Timed out connecting Nanny '<Nanny: None, threads: 1>' to scheduler 'tcp://172.30.100.4:42246'
Traceback (most recent call last):
  File "/scratch/cnt0024/hmg2840/albert7a/anaconda3/lib/python3.7/site-packages/distributed/nanny.py", line 303, in instantiate
    timedelta(seconds=self.death_timeout), self.process.start()
  File "/scratch/cnt0024/hmg2840/albert7a/anaconda3/lib/python3.7/site-packages/tornado/gen.py", line 729, in run
    value = future.result()
tornado.util.TimeoutError: Timeout
distributed.nanny - ERROR - Timed out connecting Nanny '<Nanny: None, threads: 1>' to scheduler 'tcp://172.30.100.4:42246'
Traceback (most recent call last):
  File "/scratch/cnt0024/hmg2840/albert7a/anaconda3/lib/python3.7/site-packages/distributed/nanny.py", line 303, in instantiate
    timedelta(seconds=self.death_timeout), self.process.start()
  File "/scratch/cnt0024/hmg2840/albert7a/anaconda3/lib/python3.7/site-packages/tornado/gen.py", line 729, in run
    value = future.result()
tornado.util.TimeoutError: Timeout
distributed.nanny - ERROR - Timed out connecting Nanny '<Nanny: None, threads: 1>' to scheduler 'tcp://172.30.100.4:42246'
Traceback (most recent call last):
  File "/scratch/cnt0024/hmg2840/albert7a/anaconda3/lib/python3.7/site-packages/distributed/nanny.py", line 303, in instantiate
    timedelta(seconds=self.death_timeout), self.process.start()
  File "/scratch/cnt0024/hmg2840/albert7a/anaconda3/lib/python3.7/site-packages/tornado/gen.py", line 729, in run
    value = future.result()
tornado.util.TimeoutError: Timeout
distributed.nanny - ERROR - Timed out connecting Nanny '<Nanny: None, threads: 1>' to scheduler 'tcp://172.30.100.4:42246'
Traceback (most recent call last):
  File "/scratch/cnt0024/hmg2840/albert7a/anaconda3/lib/python3.7/site-packages/distributed/nanny.py", line 303, in instantiate
    timedelta(seconds=self.death_timeout), self.process.start()
  File "/scratch/cnt0024/hmg2840/albert7a/anaconda3/lib/python3.7/site-packages/tornado/gen.py", line 729, in run
    value = future.result()
tornado.util.TimeoutError: Timeout
distributed.nanny - ERROR - Timed out connecting Nanny '<Nanny: None, threads: 1>' to scheduler 'tcp://172.30.100.4:42246'
Traceback (most recent call last):
  File "/scratch/cnt0024/hmg2840/albert7a/anaconda3/lib/python3.7/site-packages/distributed/nanny.py", line 303, in instantiate
    timedelta(seconds=self.death_timeout), self.process.start()
  File "/scratch/cnt0024/hmg2840/albert7a/anaconda3/lib/python3.7/site-packages/tornado/gen.py", line 729, in run
    value = future.result()
tornado.util.TimeoutError: Timeout
distributed.nanny - ERROR - Timed out connecting Nanny '<Nanny: None, threads: 1>' to scheduler 'tcp://172.30.100.4:42246'
Traceback (most recent call last):
  File "/scratch/cnt0024/hmg2840/albert7a/anaconda3/lib/python3.7/site-packages/distributed/nanny.py", line 303, in instantiate
    timedelta(seconds=self.death_timeout), self.process.start()
  File "/scratch/cnt0024/hmg2840/albert7a/anaconda3/lib/python3.7/site-packages/tornado/gen.py", line 729, in run
    value = future.result()
tornado.util.TimeoutError: Timeout
distributed.nanny - ERROR - Timed out connecting Nanny '<Nanny: None, threads: 1>' to scheduler 'tcp://172.30.100.4:42246'
Traceback (most recent call last):
  File "/scratch/cnt0024/hmg2840/albert7a/anaconda3/lib/python3.7/site-packages/distributed/nanny.py", line 303, in instantiate
    timedelta(seconds=self.death_timeout), self.process.start()
  File "/scratch/cnt0024/hmg2840/albert7a/anaconda3/lib/python3.7/site-packages/tornado/gen.py", line 729, in run
    value = future.result()
tornado.util.TimeoutError: Timeout
distributed.nanny - ERROR - Timed out connecting Nanny '<Nanny: None, threads: 1>' to scheduler 'tcp://172.30.100.4:42246'
Traceback (most recent call last):
  File "/scratch/cnt0024/hmg2840/albert7a/anaconda3/lib/python3.7/site-packages/distributed/nanny.py", line 303, in instantiate
    timedelta(seconds=self.death_timeout), self.process.start()
  File "/scratch/cnt0024/hmg2840/albert7a/anaconda3/lib/python3.7/site-packages/tornado/gen.py", line 729, in run
    value = future.result()
tornado.util.TimeoutError: Timeout
distributed.nanny - ERROR - Timed out connecting Nanny '<Nanny: None, threads: 1>' to scheduler 'tcp://172.30.100.4:42246'
Traceback (most recent call last):
  File "/scratch/cnt0024/hmg2840/albert7a/anaconda3/lib/python3.7/site-packages/distributed/nanny.py", line 303, in instantiate
    timedelta(seconds=self.death_timeout), self.process.start()
  File "/scratch/cnt0024/hmg2840/albert7a/anaconda3/lib/python3.7/site-packages/tornado/gen.py", line 729, in run
    value = future.result()
tornado.util.TimeoutError: Timeout
distributed.nanny - ERROR - Timed out connecting Nanny '<Nanny: None, threads: 1>' to scheduler 'tcp://172.30.100.4:42246'
Traceback (most recent call last):
  File "/scratch/cnt0024/hmg2840/albert7a/anaconda3/lib/python3.7/site-packages/distributed/nanny.py", line 303, in instantiate
    timedelta(seconds=self.death_timeout), self.process.start()
  File "/scratch/cnt0024/hmg2840/albert7a/anaconda3/lib/python3.7/site-packages/tornado/gen.py", line 729, in run
    value = future.result()
tornado.util.TimeoutError: Timeout
distributed.nanny - ERROR - Timed out connecting Nanny '<Nanny: None, threads: 1>' to scheduler 'tcp://172.30.100.4:42246'
Traceback (most recent call last):
  File "/scratch/cnt0024/hmg2840/albert7a/anaconda3/lib/python3.7/site-packages/distributed/nanny.py", line 303, in instantiate
    timedelta(seconds=self.death_timeout), self.process.start()
  File "/scratch/cnt0024/hmg2840/albert7a/anaconda3/lib/python3.7/site-packages/tornado/gen.py", line 729, in run
    value = future.result()
tornado.util.TimeoutError: Timeout
distributed.nanny - ERROR - Timed out connecting Nanny '<Nanny: None, threads: 1>' to scheduler 'tcp://172.30.100.4:42246'
Traceback (most recent call last):
  File "/scratch/cnt0024/hmg2840/albert7a/anaconda3/lib/python3.7/site-packages/distributed/nanny.py", line 303, in instantiate
    timedelta(seconds=self.death_timeout), self.process.start()
  File "/scratch/cnt0024/hmg2840/albert7a/anaconda3/lib/python3.7/site-packages/tornado/gen.py", line 729, in run
    value = future.result()
tornado.util.TimeoutError: Timeout
distributed.nanny - ERROR - Timed out connecting Nanny '<Nanny: None, threads: 1>' to scheduler 'tcp://172.30.100.4:42246'
Traceback (most recent call last):
  File "/scratch/cnt0024/hmg2840/albert7a/anaconda3/lib/python3.7/site-packages/distributed/nanny.py", line 303, in instantiate
    timedelta(seconds=self.death_timeout), self.process.start()
  File "/scratch/cnt0024/hmg2840/albert7a/anaconda3/lib/python3.7/site-packages/tornado/gen.py", line 729, in run
    value = future.result()
tornado.util.TimeoutError: Timeout
distributed.nanny - ERROR - Timed out connecting Nanny '<Nanny: None, threads: 1>' to scheduler 'tcp://172.30.100.4:42246'
Traceback (most recent call last):
  File "/scratch/cnt0024/hmg2840/albert7a/anaconda3/lib/python3.7/site-packages/distributed/nanny.py", line 303, in instantiate
    timedelta(seconds=self.death_timeout), self.process.start()
  File "/scratch/cnt0024/hmg2840/albert7a/anaconda3/lib/python3.7/site-packages/tornado/gen.py", line 729, in run
    value = future.result()
tornado.util.TimeoutError: Timeout
distributed.nanny - ERROR - Timed out connecting Nanny '<Nanny: None, threads: 1>' to scheduler 'tcp://172.30.100.4:42246'
Traceback (most recent call last):
  File "/scratch/cnt0024/hmg2840/albert7a/anaconda3/lib/python3.7/site-packages/distributed/nanny.py", line 303, in instantiate
    timedelta(seconds=self.death_timeout), self.process.start()
  File "/scratch/cnt0024/hmg2840/albert7a/anaconda3/lib/python3.7/site-packages/tornado/gen.py", line 729, in run
    value = future.result()
tornado.util.TimeoutError: Timeout
distributed.nanny - ERROR - Timed out connecting Nanny '<Nanny: None, threads: 1>' to scheduler 'tcp://172.30.100.4:42246'
Traceback (most recent call last):
  File "/scratch/cnt0024/hmg2840/albert7a/anaconda3/lib/python3.7/site-packages/distributed/nanny.py", line 303, in instantiate
    timedelta(seconds=self.death_timeout), self.process.start()
  File "/scratch/cnt0024/hmg2840/albert7a/anaconda3/lib/python3.7/site-packages/tornado/gen.py", line 729, in run
    value = future.result()
tornado.util.TimeoutError: Timeout
distributed.nanny - ERROR - Timed out connecting Nanny '<Nanny: None, threads: 1>' to scheduler 'tcp://172.30.100.4:42246'
Traceback (most recent call last):
  File "/scratch/cnt0024/hmg2840/albert7a/anaconda3/lib/python3.7/site-packages/distributed/nanny.py", line 303, in instantiate
    timedelta(seconds=self.death_timeout), self.process.start()
  File "/scratch/cnt0024/hmg2840/albert7a/anaconda3/lib/python3.7/site-packages/tornado/gen.py", line 729, in run
    value = future.result()
tornado.util.TimeoutError: Timeout
distributed.nanny - ERROR - Timed out connecting Nanny '<Nanny: None, threads: 1>' to scheduler 'tcp://172.30.100.4:42246'
Traceback (most recent call last):
  File "/scratch/cnt0024/hmg2840/albert7a/anaconda3/lib/python3.7/site-packages/distributed/nanny.py", line 303, in instantiate
    timedelta(seconds=self.death_timeout), self.process.start()
  File "/scratch/cnt0024/hmg2840/albert7a/anaconda3/lib/python3.7/site-packages/tornado/gen.py", line 729, in run
    value = future.result()
tornado.util.TimeoutError: Timeout
distributed.nanny - ERROR - Timed out connecting Nanny '<Nanny: None, threads: 1>' to scheduler 'tcp://172.30.100.4:42246'
Traceback (most recent call last):
  File "/scratch/cnt0024/hmg2840/albert7a/anaconda3/lib/python3.7/site-packages/distributed/nanny.py", line 303, in instantiate
    timedelta(seconds=self.death_timeout), self.process.start()
  File "/scratch/cnt0024/hmg2840/albert7a/anaconda3/lib/python3.7/site-packages/tornado/gen.py", line 729, in run
    value = future.result()
tornado.util.TimeoutError: Timeout
tornado.application - ERROR - Multiple exceptions in yield list
Traceback (most recent call last):
  File "/scratch/cnt0024/hmg2840/albert7a/anaconda3/lib/python3.7/site-packages/tornado/gen.py", line 501, in callback
    result_list.append(f.result())
  File "/scratch/cnt0024/hmg2840/albert7a/anaconda3/lib/python3.7/asyncio/tasks.py", line 603, in _wrap_awaitable
    return (yield from awaitable.__await__())
  File "/scratch/cnt0024/hmg2840/albert7a/anaconda3/lib/python3.7/site-packages/tornado/gen.py", line 736, in run
    yielded = self.gen.throw(*exc_info)  # type: ignore
  File "/scratch/cnt0024/hmg2840/albert7a/anaconda3/lib/python3.7/site-packages/distributed/nanny.py", line 224, in _start
    response = yield self.instantiate()
  File "/scratch/cnt0024/hmg2840/albert7a/anaconda3/lib/python3.7/site-packages/tornado/gen.py", line 729, in run
    value = future.result()
  File "/scratch/cnt0024/hmg2840/albert7a/anaconda3/lib/python3.7/site-packages/tornado/gen.py", line 742, in run
    yielded = self.gen.send(value)
  File "/scratch/cnt0024/hmg2840/albert7a/anaconda3/lib/python3.7/site-packages/distributed/nanny.py", line 303, in instantiate
    timedelta(seconds=self.death_timeout), self.process.start()
  File "/scratch/cnt0024/hmg2840/albert7a/anaconda3/lib/python3.7/site-packages/tornado/gen.py", line 729, in run
    value = future.result()
tornado.util.TimeoutError: Timeout
tornado.application - ERROR - Multiple exceptions in yield list
Traceback (most recent call last):
  File "/scratch/cnt0024/hmg2840/albert7a/anaconda3/lib/python3.7/site-packages/tornado/gen.py", line 501, in callback
    result_list.append(f.result())
  File "/scratch/cnt0024/hmg2840/albert7a/anaconda3/lib/python3.7/asyncio/tasks.py", line 603, in _wrap_awaitable
    return (yield from awaitable.__await__())
  File "/scratch/cnt0024/hmg2840/albert7a/anaconda3/lib/python3.7/site-packages/tornado/gen.py", line 736, in run
    yielded = self.gen.throw(*exc_info)  # type: ignore
  File "/scratch/cnt0024/hmg2840/albert7a/anaconda3/lib/python3.7/site-packages/distributed/nanny.py", line 224, in _start
    response = yield self.instantiate()
  File "/scratch/cnt0024/hmg2840/albert7a/anaconda3/lib/python3.7/site-packages/tornado/gen.py", line 729, in run
    value = future.result()
  File "/scratch/cnt0024/hmg2840/albert7a/anaconda3/lib/python3.7/site-packages/tornado/gen.py", line 742, in run
    yielded = self.gen.send(value)
  File "/scratch/cnt0024/hmg2840/albert7a/anaconda3/lib/python3.7/site-packages/distributed/nanny.py", line 303, in instantiate
    timedelta(seconds=self.death_timeout), self.process.start()
  File "/scratch/cnt0024/hmg2840/albert7a/anaconda3/lib/python3.7/site-packages/tornado/gen.py", line 729, in run
    value = future.result()
tornado.util.TimeoutError: Timeout
tornado.application - ERROR - Multiple exceptions in yield list
Traceback (most recent call last):
  File "/scratch/cnt0024/hmg2840/albert7a/anaconda3/lib/python3.7/site-packages/tornado/gen.py", line 501, in callback
    result_list.append(f.result())
  File "/scratch/cnt0024/hmg2840/albert7a/anaconda3/lib/python3.7/asyncio/tasks.py", line 603, in _wrap_awaitable
    return (yield from awaitable.__await__())
  File "/scratch/cnt0024/hmg2840/albert7a/anaconda3/lib/python3.7/site-packages/tornado/gen.py", line 736, in run
    yielded = self.gen.throw(*exc_info)  # type: ignore
  File "/scratch/cnt0024/hmg2840/albert7a/anaconda3/lib/python3.7/site-packages/distributed/nanny.py", line 224, in _start
    response = yield self.instantiate()
  File "/scratch/cnt0024/hmg2840/albert7a/anaconda3/lib/python3.7/site-packages/tornado/gen.py", line 729, in run
    value = future.result()
  File "/scratch/cnt0024/hmg2840/albert7a/anaconda3/lib/python3.7/site-packages/tornado/gen.py", line 742, in run
    yielded = self.gen.send(value)
  File "/scratch/cnt0024/hmg2840/albert7a/anaconda3/lib/python3.7/site-packages/distributed/nanny.py", line 303, in instantiate
    timedelta(seconds=self.death_timeout), self.process.start()
  File "/scratch/cnt0024/hmg2840/albert7a/anaconda3/lib/python3.7/site-packages/tornado/gen.py", line 729, in run
    value = future.result()
tornado.util.TimeoutError: Timeout
tornado.application - ERROR - Multiple exceptions in yield list
Traceback (most recent call last):
  File "/scratch/cnt0024/hmg2840/albert7a/anaconda3/lib/python3.7/site-packages/tornado/gen.py", line 501, in callback
    result_list.append(f.result())
  File "/scratch/cnt0024/hmg2840/albert7a/anaconda3/lib/python3.7/asyncio/tasks.py", line 603, in _wrap_awaitable
    return (yield from awaitable.__await__())
  File "/scratch/cnt0024/hmg2840/albert7a/anaconda3/lib/python3.7/site-packages/tornado/gen.py", line 736, in run
    yielded = self.gen.throw(*exc_info)  # type: ignore
  File "/scratch/cnt0024/hmg2840/albert7a/anaconda3/lib/python3.7/site-packages/distributed/nanny.py", line 224, in _start
    response = yield self.instantiate()
  File "/scratch/cnt0024/hmg2840/albert7a/anaconda3/lib/python3.7/site-packages/tornado/gen.py", line 729, in run
    value = future.result()
  File "/scratch/cnt0024/hmg2840/albert7a/anaconda3/lib/python3.7/site-packages/tornado/gen.py", line 742, in run
    yielded = self.gen.send(value)
  File "/scratch/cnt0024/hmg2840/albert7a/anaconda3/lib/python3.7/site-packages/distributed/nanny.py", line 303, in instantiate
    timedelta(seconds=self.death_timeout), self.process.start()
  File "/scratch/cnt0024/hmg2840/albert7a/anaconda3/lib/python3.7/site-packages/tornado/gen.py", line 729, in run
    value = future.result()
tornado.util.TimeoutError: Timeout
tornado.application - ERROR - Multiple exceptions in yield list
Traceback (most recent call last):
  File "/scratch/cnt0024/hmg2840/albert7a/anaconda3/lib/python3.7/site-packages/tornado/gen.py", line 501, in callback
    result_list.append(f.result())
  File "/scratch/cnt0024/hmg2840/albert7a/anaconda3/lib/python3.7/asyncio/tasks.py", line 603, in _wrap_awaitable
    return (yield from awaitable.__await__())
  File "/scratch/cnt0024/hmg2840/albert7a/anaconda3/lib/python3.7/site-packages/tornado/gen.py", line 736, in run
    yielded = self.gen.throw(*exc_info)  # type: ignore
  File "/scratch/cnt0024/hmg2840/albert7a/anaconda3/lib/python3.7/site-packages/distributed/nanny.py", line 224, in _start
    response = yield self.instantiate()
  File "/scratch/cnt0024/hmg2840/albert7a/anaconda3/lib/python3.7/site-packages/tornado/gen.py", line 729, in run
    value = future.result()
  File "/scratch/cnt0024/hmg2840/albert7a/anaconda3/lib/python3.7/site-packages/tornado/gen.py", line 742, in run
    yielded = self.gen.send(value)
  File "/scratch/cnt0024/hmg2840/albert7a/anaconda3/lib/python3.7/site-packages/distributed/nanny.py", line 303, in instantiate
    timedelta(seconds=self.death_timeout), self.process.start()
  File "/scratch/cnt0024/hmg2840/albert7a/anaconda3/lib/python3.7/site-packages/tornado/gen.py", line 729, in run
    value = future.result()
tornado.util.TimeoutError: Timeout
tornado.application - ERROR - Multiple exceptions in yield list
Traceback (most recent call last):
  File "/scratch/cnt0024/hmg2840/albert7a/anaconda3/lib/python3.7/site-packages/tornado/gen.py", line 501, in callback
    result_list.append(f.result())
  File "/scratch/cnt0024/hmg2840/albert7a/anaconda3/lib/python3.7/asyncio/tasks.py", line 603, in _wrap_awaitable
    return (yield from awaitable.__await__())
  File "/scratch/cnt0024/hmg2840/albert7a/anaconda3/lib/python3.7/site-packages/tornado/gen.py", line 736, in run
    yielded = self.gen.throw(*exc_info)  # type: ignore
  File "/scratch/cnt0024/hmg2840/albert7a/anaconda3/lib/python3.7/site-packages/distributed/nanny.py", line 224, in _start
    response = yield self.instantiate()
  File "/scratch/cnt0024/hmg2840/albert7a/anaconda3/lib/python3.7/site-packages/tornado/gen.py", line 729, in run
    value = future.result()
  File "/scratch/cnt0024/hmg2840/albert7a/anaconda3/lib/python3.7/site-packages/tornado/gen.py", line 742, in run
    yielded = self.gen.send(value)
  File "/scratch/cnt0024/hmg2840/albert7a/anaconda3/lib/python3.7/site-packages/distributed/nanny.py", line 303, in instantiate
    timedelta(seconds=self.death_timeout), self.process.start()
  File "/scratch/cnt0024/hmg2840/albert7a/anaconda3/lib/python3.7/site-packages/tornado/gen.py", line 729, in run
    value = future.result()
tornado.util.TimeoutError: Timeout
tornado.application - ERROR - Multiple exceptions in yield list
Traceback (most recent call last):
  File "/scratch/cnt0024/hmg2840/albert7a/anaconda3/lib/python3.7/site-packages/tornado/gen.py", line 501, in callback
    result_list.append(f.result())
  File "/scratch/cnt0024/hmg2840/albert7a/anaconda3/lib/python3.7/asyncio/tasks.py", line 603, in _wrap_awaitable
    return (yield from awaitable.__await__())
  File "/scratch/cnt0024/hmg2840/albert7a/anaconda3/lib/python3.7/site-packages/tornado/gen.py", line 736, in run
    yielded = self.gen.throw(*exc_info)  # type: ignore
  File "/scratch/cnt0024/hmg2840/albert7a/anaconda3/lib/python3.7/site-packages/distributed/nanny.py", line 224, in _start
    response = yield self.instantiate()
  File "/scratch/cnt0024/hmg2840/albert7a/anaconda3/lib/python3.7/site-packages/tornado/gen.py", line 729, in run
    value = future.result()
  File "/scratch/cnt0024/hmg2840/albert7a/anaconda3/lib/python3.7/site-packages/tornado/gen.py", line 742, in run
    yielded = self.gen.send(value)
  File "/scratch/cnt0024/hmg2840/albert7a/anaconda3/lib/python3.7/site-packages/distributed/nanny.py", line 303, in instantiate
    timedelta(seconds=self.death_timeout), self.process.start()
  File "/scratch/cnt0024/hmg2840/albert7a/anaconda3/lib/python3.7/site-packages/tornado/gen.py", line 729, in run
    value = future.result()
tornado.util.TimeoutError: Timeout
tornado.application - ERROR - Multiple exceptions in yield list
Traceback (most recent call last):
  File "/scratch/cnt0024/hmg2840/albert7a/anaconda3/lib/python3.7/site-packages/tornado/gen.py", line 501, in callback
    result_list.append(f.result())
  File "/scratch/cnt0024/hmg2840/albert7a/anaconda3/lib/python3.7/asyncio/tasks.py", line 603, in _wrap_awaitable
    return (yield from awaitable.__await__())
  File "/scratch/cnt0024/hmg2840/albert7a/anaconda3/lib/python3.7/site-packages/tornado/gen.py", line 736, in run
    yielded = self.gen.throw(*exc_info)  # type: ignore
  File "/scratch/cnt0024/hmg2840/albert7a/anaconda3/lib/python3.7/site-packages/distributed/nanny.py", line 224, in _start
    response = yield self.instantiate()
  File "/scratch/cnt0024/hmg2840/albert7a/anaconda3/lib/python3.7/site-packages/tornado/gen.py", line 729, in run
    value = future.result()
  File "/scratch/cnt0024/hmg2840/albert7a/anaconda3/lib/python3.7/site-packages/tornado/gen.py", line 742, in run
    yielded = self.gen.send(value)
  File "/scratch/cnt0024/hmg2840/albert7a/anaconda3/lib/python3.7/site-packages/distributed/nanny.py", line 303, in instantiate
    timedelta(seconds=self.death_timeout), self.process.start()
  File "/scratch/cnt0024/hmg2840/albert7a/anaconda3/lib/python3.7/site-packages/tornado/gen.py", line 729, in run
    value = future.result()
tornado.util.TimeoutError: Timeout
tornado.application - ERROR - Multiple exceptions in yield list
Traceback (most recent call last):
  File "/scratch/cnt0024/hmg2840/albert7a/anaconda3/lib/python3.7/site-packages/tornado/gen.py", line 501, in callback
    result_list.append(f.result())
  File "/scratch/cnt0024/hmg2840/albert7a/anaconda3/lib/python3.7/asyncio/tasks.py", line 603, in _wrap_awaitable
    return (yield from awaitable.__await__())
  File "/scratch/cnt0024/hmg2840/albert7a/anaconda3/lib/python3.7/site-packages/tornado/gen.py", line 736, in run
    yielded = self.gen.throw(*exc_info)  # type: ignore
  File "/scratch/cnt0024/hmg2840/albert7a/anaconda3/lib/python3.7/site-packages/distributed/nanny.py", line 224, in _start
    response = yield self.instantiate()
  File "/scratch/cnt0024/hmg2840/albert7a/anaconda3/lib/python3.7/site-packages/tornado/gen.py", line 729, in run
    value = future.result()
  File "/scratch/cnt0024/hmg2840/albert7a/anaconda3/lib/python3.7/site-packages/tornado/gen.py", line 742, in run
    yielded = self.gen.send(value)
  File "/scratch/cnt0024/hmg2840/albert7a/anaconda3/lib/python3.7/site-packages/distributed/nanny.py", line 303, in instantiate
    timedelta(seconds=self.death_timeout), self.process.start()
  File "/scratch/cnt0024/hmg2840/albert7a/anaconda3/lib/python3.7/site-packages/tornado/gen.py", line 729, in run
    value = future.result()
tornado.util.TimeoutError: Timeout
tornado.application - ERROR - Multiple exceptions in yield list
Traceback (most recent call last):
  File "/scratch/cnt0024/hmg2840/albert7a/anaconda3/lib/python3.7/site-packages/tornado/gen.py", line 501, in callback
    result_list.append(f.result())
  File "/scratch/cnt0024/hmg2840/albert7a/anaconda3/lib/python3.7/asyncio/tasks.py", line 603, in _wrap_awaitable
    return (yield from awaitable.__await__())
  File "/scratch/cnt0024/hmg2840/albert7a/anaconda3/lib/python3.7/site-packages/tornado/gen.py", line 736, in run
    yielded = self.gen.throw(*exc_info)  # type: ignore
  File "/scratch/cnt0024/hmg2840/albert7a/anaconda3/lib/python3.7/site-packages/distributed/nanny.py", line 224, in _start
    response = yield self.instantiate()
  File "/scratch/cnt0024/hmg2840/albert7a/anaconda3/lib/python3.7/site-packages/tornado/gen.py", line 729, in run
    value = future.result()
  File "/scratch/cnt0024/hmg2840/albert7a/anaconda3/lib/python3.7/site-packages/tornado/gen.py", line 742, in run
    yielded = self.gen.send(value)
  File "/scratch/cnt0024/hmg2840/albert7a/anaconda3/lib/python3.7/site-packages/distributed/nanny.py", line 303, in instantiate
    timedelta(seconds=self.death_timeout), self.process.start()
  File "/scratch/cnt0024/hmg2840/albert7a/anaconda3/lib/python3.7/site-packages/tornado/gen.py", line 729, in run
    value = future.result()
tornado.util.TimeoutError: Timeout
tornado.application - ERROR - Multiple exceptions in yield list
Traceback (most recent call last):
  File "/scratch/cnt0024/hmg2840/albert7a/anaconda3/lib/python3.7/site-packages/tornado/gen.py", line 501, in callback
    result_list.append(f.result())
  File "/scratch/cnt0024/hmg2840/albert7a/anaconda3/lib/python3.7/asyncio/tasks.py", line 603, in _wrap_awaitable
    return (yield from awaitable.__await__())
  File "/scratch/cnt0024/hmg2840/albert7a/anaconda3/lib/python3.7/site-packages/tornado/gen.py", line 736, in run
    yielded = self.gen.throw(*exc_info)  # type: ignore
  File "/scratch/cnt0024/hmg2840/albert7a/anaconda3/lib/python3.7/site-packages/distributed/nanny.py", line 224, in _start
    response = yield self.instantiate()
  File "/scratch/cnt0024/hmg2840/albert7a/anaconda3/lib/python3.7/site-packages/tornado/gen.py", line 729, in run
    value = future.result()
  File "/scratch/cnt0024/hmg2840/albert7a/anaconda3/lib/python3.7/site-packages/tornado/gen.py", line 742, in run
    yielded = self.gen.send(value)
  File "/scratch/cnt0024/hmg2840/albert7a/anaconda3/lib/python3.7/site-packages/distributed/nanny.py", line 303, in instantiate
    timedelta(seconds=self.death_timeout), self.process.start()
  File "/scratch/cnt0024/hmg2840/albert7a/anaconda3/lib/python3.7/site-packages/tornado/gen.py", line 729, in run
    value = future.result()
tornado.util.TimeoutError: Timeout
tornado.application - ERROR - Multiple exceptions in yield list
Traceback (most recent call last):
  File "/scratch/cnt0024/hmg2840/albert7a/anaconda3/lib/python3.7/site-packages/tornado/gen.py", line 501, in callback
    result_list.append(f.result())
  File "/scratch/cnt0024/hmg2840/albert7a/anaconda3/lib/python3.7/asyncio/tasks.py", line 603, in _wrap_awaitable
    return (yield from awaitable.__await__())
  File "/scratch/cnt0024/hmg2840/albert7a/anaconda3/lib/python3.7/site-packages/tornado/gen.py", line 736, in run
    yielded = self.gen.throw(*exc_info)  # type: ignore
  File "/scratch/cnt0024/hmg2840/albert7a/anaconda3/lib/python3.7/site-packages/distributed/nanny.py", line 224, in _start
    response = yield self.instantiate()
  File "/scratch/cnt0024/hmg2840/albert7a/anaconda3/lib/python3.7/site-packages/tornado/gen.py", line 729, in run
    value = future.result()
  File "/scratch/cnt0024/hmg2840/albert7a/anaconda3/lib/python3.7/site-packages/tornado/gen.py", line 742, in run
    yielded = self.gen.send(value)
  File "/scratch/cnt0024/hmg2840/albert7a/anaconda3/lib/python3.7/site-packages/distributed/nanny.py", line 303, in instantiate
    timedelta(seconds=self.death_timeout), self.process.start()
  File "/scratch/cnt0024/hmg2840/albert7a/anaconda3/lib/python3.7/site-packages/tornado/gen.py", line 729, in run
    value = future.result()
tornado.util.TimeoutError: Timeout
tornado.application - ERROR - Multiple exceptions in yield list
Traceback (most recent call last):
  File "/scratch/cnt0024/hmg2840/albert7a/anaconda3/lib/python3.7/site-packages/tornado/gen.py", line 501, in callback
    result_list.append(f.result())
  File "/scratch/cnt0024/hmg2840/albert7a/anaconda3/lib/python3.7/asyncio/tasks.py", line 603, in _wrap_awaitable
    return (yield from awaitable.__await__())
  File "/scratch/cnt0024/hmg2840/albert7a/anaconda3/lib/python3.7/site-packages/tornado/gen.py", line 736, in run
    yielded = self.gen.throw(*exc_info)  # type: ignore
  File "/scratch/cnt0024/hmg2840/albert7a/anaconda3/lib/python3.7/site-packages/distributed/nanny.py", line 224, in _start
    response = yield self.instantiate()
  File "/scratch/cnt0024/hmg2840/albert7a/anaconda3/lib/python3.7/site-packages/tornado/gen.py", line 729, in run
    value = future.result()
  File "/scratch/cnt0024/hmg2840/albert7a/anaconda3/lib/python3.7/site-packages/tornado/gen.py", line 742, in run
    yielded = self.gen.send(value)
  File "/scratch/cnt0024/hmg2840/albert7a/anaconda3/lib/python3.7/site-packages/distributed/nanny.py", line 303, in instantiate
    timedelta(seconds=self.death_timeout), self.process.start()
  File "/scratch/cnt0024/hmg2840/albert7a/anaconda3/lib/python3.7/site-packages/tornado/gen.py", line 729, in run
    value = future.result()
tornado.util.TimeoutError: Timeout
tornado.application - ERROR - Multiple exceptions in yield list
Traceback (most recent call last):
  File "/scratch/cnt0024/hmg2840/albert7a/anaconda3/lib/python3.7/site-packages/tornado/gen.py", line 501, in callback
    result_list.append(f.result())
  File "/scratch/cnt0024/hmg2840/albert7a/anaconda3/lib/python3.7/asyncio/tasks.py", line 603, in _wrap_awaitable
    return (yield from awaitable.__await__())
  File "/scratch/cnt0024/hmg2840/albert7a/anaconda3/lib/python3.7/site-packages/tornado/gen.py", line 736, in run
    yielded = self.gen.throw(*exc_info)  # type: ignore
  File "/scratch/cnt0024/hmg2840/albert7a/anaconda3/lib/python3.7/site-packages/distributed/nanny.py", line 224, in _start
    response = yield self.instantiate()
  File "/scratch/cnt0024/hmg2840/albert7a/anaconda3/lib/python3.7/site-packages/tornado/gen.py", line 729, in run
    value = future.result()
  File "/scratch/cnt0024/hmg2840/albert7a/anaconda3/lib/python3.7/site-packages/tornado/gen.py", line 742, in run
    yielded = self.gen.send(value)
  File "/scratch/cnt0024/hmg2840/albert7a/anaconda3/lib/python3.7/site-packages/distributed/nanny.py", line 303, in instantiate
    timedelta(seconds=self.death_timeout), self.process.start()
  File "/scratch/cnt0024/hmg2840/albert7a/anaconda3/lib/python3.7/site-packages/tornado/gen.py", line 729, in run
    value = future.result()
tornado.util.TimeoutError: Timeout
tornado.application - ERROR - Multiple exceptions in yield list
Traceback (most recent call last):
  File "/scratch/cnt0024/hmg2840/albert7a/anaconda3/lib/python3.7/site-packages/tornado/gen.py", line 501, in callback
    result_list.append(f.result())
  File "/scratch/cnt0024/hmg2840/albert7a/anaconda3/lib/python3.7/asyncio/tasks.py", line 603, in _wrap_awaitable
    return (yield from awaitable.__await__())
  File "/scratch/cnt0024/hmg2840/albert7a/anaconda3/lib/python3.7/site-packages/tornado/gen.py", line 736, in run
    yielded = self.gen.throw(*exc_info)  # type: ignore
  File "/scratch/cnt0024/hmg2840/albert7a/anaconda3/lib/python3.7/site-packages/distributed/nanny.py", line 224, in _start
    response = yield self.instantiate()
  File "/scratch/cnt0024/hmg2840/albert7a/anaconda3/lib/python3.7/site-packages/tornado/gen.py", line 729, in run
    value = future.result()
  File "/scratch/cnt0024/hmg2840/albert7a/anaconda3/lib/python3.7/site-packages/tornado/gen.py", line 742, in run
    yielded = self.gen.send(value)
  File "/scratch/cnt0024/hmg2840/albert7a/anaconda3/lib/python3.7/site-packages/distributed/nanny.py", line 303, in instantiate
    timedelta(seconds=self.death_timeout), self.process.start()
  File "/scratch/cnt0024/hmg2840/albert7a/anaconda3/lib/python3.7/site-packages/tornado/gen.py", line 729, in run
    value = future.result()
tornado.util.TimeoutError: Timeout
tornado.application - ERROR - Multiple exceptions in yield list
Traceback (most recent call last):
  File "/scratch/cnt0024/hmg2840/albert7a/anaconda3/lib/python3.7/site-packages/tornado/gen.py", line 501, in callback
    result_list.append(f.result())
  File "/scratch/cnt0024/hmg2840/albert7a/anaconda3/lib/python3.7/asyncio/tasks.py", line 603, in _wrap_awaitable
    return (yield from awaitable.__await__())
  File "/scratch/cnt0024/hmg2840/albert7a/anaconda3/lib/python3.7/site-packages/tornado/gen.py", line 736, in run
    yielded = self.gen.throw(*exc_info)  # type: ignore
  File "/scratch/cnt0024/hmg2840/albert7a/anaconda3/lib/python3.7/site-packages/distributed/nanny.py", line 224, in _start
    response = yield self.instantiate()
  File "/scratch/cnt0024/hmg2840/albert7a/anaconda3/lib/python3.7/site-packages/tornado/gen.py", line 729, in run
    value = future.result()
  File "/scratch/cnt0024/hmg2840/albert7a/anaconda3/lib/python3.7/site-packages/tornado/gen.py", line 742, in run
    yielded = self.gen.send(value)
  File "/scratch/cnt0024/hmg2840/albert7a/anaconda3/lib/python3.7/site-packages/distributed/nanny.py", line 303, in instantiate
    timedelta(seconds=self.death_timeout), self.process.start()
  File "/scratch/cnt0024/hmg2840/albert7a/anaconda3/lib/python3.7/site-packages/tornado/gen.py", line 729, in run
    value = future.result()
tornado.util.TimeoutError: Timeout
tornado.application - ERROR - Multiple exceptions in yield list
Traceback (most recent call last):
  File "/scratch/cnt0024/hmg2840/albert7a/anaconda3/lib/python3.7/site-packages/tornado/gen.py", line 501, in callback
    result_list.append(f.result())
  File "/scratch/cnt0024/hmg2840/albert7a/anaconda3/lib/python3.7/asyncio/tasks.py", line 603, in _wrap_awaitable
    return (yield from awaitable.__await__())
  File "/scratch/cnt0024/hmg2840/albert7a/anaconda3/lib/python3.7/site-packages/tornado/gen.py", line 736, in run
    yielded = self.gen.throw(*exc_info)  # type: ignore
  File "/scratch/cnt0024/hmg2840/albert7a/anaconda3/lib/python3.7/site-packages/distributed/nanny.py", line 224, in _start
    response = yield self.instantiate()
  File "/scratch/cnt0024/hmg2840/albert7a/anaconda3/lib/python3.7/site-packages/tornado/gen.py", line 729, in run
    value = future.result()
  File "/scratch/cnt0024/hmg2840/albert7a/anaconda3/lib/python3.7/site-packages/tornado/gen.py", line 742, in run
    yielded = self.gen.send(value)
  File "/scratch/cnt0024/hmg2840/albert7a/anaconda3/lib/python3.7/site-packages/distributed/nanny.py", line 303, in instantiate
    timedelta(seconds=self.death_timeout), self.process.start()
  File "/scratch/cnt0024/hmg2840/albert7a/anaconda3/lib/python3.7/site-packages/tornado/gen.py", line 729, in run
    value = future.result()
tornado.util.TimeoutError: Timeout
tornado.application - ERROR - Multiple exceptions in yield list
Traceback (most recent call last):
  File "/scratch/cnt0024/hmg2840/albert7a/anaconda3/lib/python3.7/site-packages/tornado/gen.py", line 501, in callback
    result_list.append(f.result())
  File "/scratch/cnt0024/hmg2840/albert7a/anaconda3/lib/python3.7/asyncio/tasks.py", line 603, in _wrap_awaitable
    return (yield from awaitable.__await__())
  File "/scratch/cnt0024/hmg2840/albert7a/anaconda3/lib/python3.7/site-packages/tornado/gen.py", line 736, in run
    yielded = self.gen.throw(*exc_info)  # type: ignore
  File "/scratch/cnt0024/hmg2840/albert7a/anaconda3/lib/python3.7/site-packages/distributed/nanny.py", line 224, in _start
    response = yield self.instantiate()
  File "/scratch/cnt0024/hmg2840/albert7a/anaconda3/lib/python3.7/site-packages/tornado/gen.py", line 729, in run
    value = future.result()
  File "/scratch/cnt0024/hmg2840/albert7a/anaconda3/lib/python3.7/site-packages/tornado/gen.py", line 742, in run
    yielded = self.gen.send(value)
  File "/scratch/cnt0024/hmg2840/albert7a/anaconda3/lib/python3.7/site-packages/distributed/nanny.py", line 303, in instantiate
    timedelta(seconds=self.death_timeout), self.process.start()
  File "/scratch/cnt0024/hmg2840/albert7a/anaconda3/lib/python3.7/site-packages/tornado/gen.py", line 729, in run
    value = future.result()
tornado.util.TimeoutError: Timeout
tornado.application - ERROR - Multiple exceptions in yield list
Traceback (most recent call last):
  File "/scratch/cnt0024/hmg2840/albert7a/anaconda3/lib/python3.7/site-packages/tornado/gen.py", line 501, in callback
    result_list.append(f.result())
  File "/scratch/cnt0024/hmg2840/albert7a/anaconda3/lib/python3.7/asyncio/tasks.py", line 603, in _wrap_awaitable
    return (yield from awaitable.__await__())
  File "/scratch/cnt0024/hmg2840/albert7a/anaconda3/lib/python3.7/site-packages/tornado/gen.py", line 736, in run
    yielded = self.gen.throw(*exc_info)  # type: ignore
  File "/scratch/cnt0024/hmg2840/albert7a/anaconda3/lib/python3.7/site-packages/distributed/nanny.py", line 224, in _start
    response = yield self.instantiate()
  File "/scratch/cnt0024/hmg2840/albert7a/anaconda3/lib/python3.7/site-packages/tornado/gen.py", line 729, in run
    value = future.result()
  File "/scratch/cnt0024/hmg2840/albert7a/anaconda3/lib/python3.7/site-packages/tornado/gen.py", line 742, in run
    yielded = self.gen.send(value)
  File "/scratch/cnt0024/hmg2840/albert7a/anaconda3/lib/python3.7/site-packages/distributed/nanny.py", line 303, in instantiate
    timedelta(seconds=self.death_timeout), self.process.start()
  File "/scratch/cnt0024/hmg2840/albert7a/anaconda3/lib/python3.7/site-packages/tornado/gen.py", line 729, in run
    value = future.result()
tornado.util.TimeoutError: Timeout
tornado.application - ERROR - Multiple exceptions in yield list
Traceback (most recent call last):
  File "/scratch/cnt0024/hmg2840/albert7a/anaconda3/lib/python3.7/site-packages/tornado/gen.py", line 501, in callback
    result_list.append(f.result())
  File "/scratch/cnt0024/hmg2840/albert7a/anaconda3/lib/python3.7/asyncio/tasks.py", line 603, in _wrap_awaitable
    return (yield from awaitable.__await__())
  File "/scratch/cnt0024/hmg2840/albert7a/anaconda3/lib/python3.7/site-packages/tornado/gen.py", line 736, in run
    yielded = self.gen.throw(*exc_info)  # type: ignore
  File "/scratch/cnt0024/hmg2840/albert7a/anaconda3/lib/python3.7/site-packages/distributed/nanny.py", line 224, in _start
    response = yield self.instantiate()
  File "/scratch/cnt0024/hmg2840/albert7a/anaconda3/lib/python3.7/site-packages/tornado/gen.py", line 729, in run
    value = future.result()
  File "/scratch/cnt0024/hmg2840/albert7a/anaconda3/lib/python3.7/site-packages/tornado/gen.py", line 742, in run
    yielded = self.gen.send(value)
  File "/scratch/cnt0024/hmg2840/albert7a/anaconda3/lib/python3.7/site-packages/distributed/nanny.py", line 303, in instantiate
    timedelta(seconds=self.death_timeout), self.process.start()
  File "/scratch/cnt0024/hmg2840/albert7a/anaconda3/lib/python3.7/site-packages/tornado/gen.py", line 729, in run
    value = future.result()
tornado.util.TimeoutError: Timeout
tornado.application - ERROR - Multiple exceptions in yield list
Traceback (most recent call last):
  File "/scratch/cnt0024/hmg2840/albert7a/anaconda3/lib/python3.7/site-packages/tornado/gen.py", line 501, in callback
    result_list.append(f.result())
  File "/scratch/cnt0024/hmg2840/albert7a/anaconda3/lib/python3.7/asyncio/tasks.py", line 603, in _wrap_awaitable
    return (yield from awaitable.__await__())
  File "/scratch/cnt0024/hmg2840/albert7a/anaconda3/lib/python3.7/site-packages/tornado/gen.py", line 736, in run
    yielded = self.gen.throw(*exc_info)  # type: ignore
  File "/scratch/cnt0024/hmg2840/albert7a/anaconda3/lib/python3.7/site-packages/distributed/nanny.py", line 224, in _start
    response = yield self.instantiate()
  File "/scratch/cnt0024/hmg2840/albert7a/anaconda3/lib/python3.7/site-packages/tornado/gen.py", line 729, in run
    value = future.result()
  File "/scratch/cnt0024/hmg2840/albert7a/anaconda3/lib/python3.7/site-packages/tornado/gen.py", line 742, in run
    yielded = self.gen.send(value)
  File "/scratch/cnt0024/hmg2840/albert7a/anaconda3/lib/python3.7/site-packages/distributed/nanny.py", line 303, in instantiate
    timedelta(seconds=self.death_timeout), self.process.start()
  File "/scratch/cnt0024/hmg2840/albert7a/anaconda3/lib/python3.7/site-packages/tornado/gen.py", line 729, in run
    value = future.result()
tornado.util.TimeoutError: Timeout
tornado.application - ERROR - Multiple exceptions in yield list
Traceback (most recent call last):
  File "/scratch/cnt0024/hmg2840/albert7a/anaconda3/lib/python3.7/site-packages/tornado/gen.py", line 501, in callback
    result_list.append(f.result())
  File "/scratch/cnt0024/hmg2840/albert7a/anaconda3/lib/python3.7/asyncio/tasks.py", line 603, in _wrap_awaitable
    return (yield from awaitable.__await__())
  File "/scratch/cnt0024/hmg2840/albert7a/anaconda3/lib/python3.7/site-packages/tornado/gen.py", line 736, in run
    yielded = self.gen.throw(*exc_info)  # type: ignore
  File "/scratch/cnt0024/hmg2840/albert7a/anaconda3/lib/python3.7/site-packages/distributed/nanny.py", line 224, in _start
    response = yield self.instantiate()
  File "/scratch/cnt0024/hmg2840/albert7a/anaconda3/lib/python3.7/site-packages/tornado/gen.py", line 729, in run
    value = future.result()
  File "/scratch/cnt0024/hmg2840/albert7a/anaconda3/lib/python3.7/site-packages/tornado/gen.py", line 742, in run
    yielded = self.gen.send(value)
  File "/scratch/cnt0024/hmg2840/albert7a/anaconda3/lib/python3.7/site-packages/distributed/nanny.py", line 303, in instantiate
    timedelta(seconds=self.death_timeout), self.process.start()
  File "/scratch/cnt0024/hmg2840/albert7a/anaconda3/lib/python3.7/site-packages/tornado/gen.py", line 729, in run
    value = future.result()
tornado.util.TimeoutError: Timeout
tornado.application - ERROR - Multiple exceptions in yield list
Traceback (most recent call last):
  File "/scratch/cnt0024/hmg2840/albert7a/anaconda3/lib/python3.7/site-packages/tornado/gen.py", line 501, in callback
    result_list.append(f.result())
  File "/scratch/cnt0024/hmg2840/albert7a/anaconda3/lib/python3.7/asyncio/tasks.py", line 603, in _wrap_awaitable
    return (yield from awaitable.__await__())
  File "/scratch/cnt0024/hmg2840/albert7a/anaconda3/lib/python3.7/site-packages/tornado/gen.py", line 736, in run
    yielded = self.gen.throw(*exc_info)  # type: ignore
  File "/scratch/cnt0024/hmg2840/albert7a/anaconda3/lib/python3.7/site-packages/distributed/nanny.py", line 224, in _start
    response = yield self.instantiate()
  File "/scratch/cnt0024/hmg2840/albert7a/anaconda3/lib/python3.7/site-packages/tornado/gen.py", line 729, in run
    value = future.result()
  File "/scratch/cnt0024/hmg2840/albert7a/anaconda3/lib/python3.7/site-packages/tornado/gen.py", line 742, in run
    yielded = self.gen.send(value)
  File "/scratch/cnt0024/hmg2840/albert7a/anaconda3/lib/python3.7/site-packages/distributed/nanny.py", line 303, in instantiate
    timedelta(seconds=self.death_timeout), self.process.start()
  File "/scratch/cnt0024/hmg2840/albert7a/anaconda3/lib/python3.7/site-packages/tornado/gen.py", line 729, in run
    value = future.result()
tornado.util.TimeoutError: Timeout
tornado.application - ERROR - Multiple exceptions in yield list
Traceback (most recent call last):
  File "/scratch/cnt0024/hmg2840/albert7a/anaconda3/lib/python3.7/site-packages/tornado/gen.py", line 501, in callback
    result_list.append(f.result())
  File "/scratch/cnt0024/hmg2840/albert7a/anaconda3/lib/python3.7/asyncio/tasks.py", line 603, in _wrap_awaitable
    return (yield from awaitable.__await__())
  File "/scratch/cnt0024/hmg2840/albert7a/anaconda3/lib/python3.7/site-packages/tornado/gen.py", line 736, in run
    yielded = self.gen.throw(*exc_info)  # type: ignore
  File "/scratch/cnt0024/hmg2840/albert7a/anaconda3/lib/python3.7/site-packages/distributed/nanny.py", line 224, in _start
    response = yield self.instantiate()
  File "/scratch/cnt0024/hmg2840/albert7a/anaconda3/lib/python3.7/site-packages/tornado/gen.py", line 729, in run
    value = future.result()
  File "/scratch/cnt0024/hmg2840/albert7a/anaconda3/lib/python3.7/site-packages/tornado/gen.py", line 742, in run
    yielded = self.gen.send(value)
  File "/scratch/cnt0024/hmg2840/albert7a/anaconda3/lib/python3.7/site-packages/distributed/nanny.py", line 303, in instantiate
    timedelta(seconds=self.death_timeout), self.process.start()
  File "/scratch/cnt0024/hmg2840/albert7a/anaconda3/lib/python3.7/site-packages/tornado/gen.py", line 729, in run
    value = future.result()
tornado.util.TimeoutError: Timeout
tornado.application - ERROR - Multiple exceptions in yield list
Traceback (most recent call last):
  File "/scratch/cnt0024/hmg2840/albert7a/anaconda3/lib/python3.7/site-packages/tornado/gen.py", line 501, in callback
    result_list.append(f.result())
  File "/scratch/cnt0024/hmg2840/albert7a/anaconda3/lib/python3.7/asyncio/tasks.py", line 603, in _wrap_awaitable
    return (yield from awaitable.__await__())
  File "/scratch/cnt0024/hmg2840/albert7a/anaconda3/lib/python3.7/site-packages/tornado/gen.py", line 736, in run
    yielded = self.gen.throw(*exc_info)  # type: ignore
  File "/scratch/cnt0024/hmg2840/albert7a/anaconda3/lib/python3.7/site-packages/distributed/nanny.py", line 224, in _start
    response = yield self.instantiate()
  File "/scratch/cnt0024/hmg2840/albert7a/anaconda3/lib/python3.7/site-packages/tornado/gen.py", line 729, in run
    value = future.result()
  File "/scratch/cnt0024/hmg2840/albert7a/anaconda3/lib/python3.7/site-packages/tornado/gen.py", line 742, in run
    yielded = self.gen.send(value)
  File "/scratch/cnt0024/hmg2840/albert7a/anaconda3/lib/python3.7/site-packages/distributed/nanny.py", line 303, in instantiate
    timedelta(seconds=self.death_timeout), self.process.start()
  File "/scratch/cnt0024/hmg2840/albert7a/anaconda3/lib/python3.7/site-packages/tornado/gen.py", line 729, in run
    value = future.result()
tornado.util.TimeoutError: Timeout
tornado.application - ERROR - Multiple exceptions in yield list
Traceback (most recent call last):
  File "/scratch/cnt0024/hmg2840/albert7a/anaconda3/lib/python3.7/site-packages/tornado/gen.py", line 501, in callback
    result_list.append(f.result())
  File "/scratch/cnt0024/hmg2840/albert7a/anaconda3/lib/python3.7/asyncio/tasks.py", line 603, in _wrap_awaitable
    return (yield from awaitable.__await__())
  File "/scratch/cnt0024/hmg2840/albert7a/anaconda3/lib/python3.7/site-packages/tornado/gen.py", line 736, in run
    yielded = self.gen.throw(*exc_info)  # type: ignore
  File "/scratch/cnt0024/hmg2840/albert7a/anaconda3/lib/python3.7/site-packages/distributed/nanny.py", line 224, in _start
    response = yield self.instantiate()
  File "/scratch/cnt0024/hmg2840/albert7a/anaconda3/lib/python3.7/site-packages/tornado/gen.py", line 729, in run
    value = future.result()
  File "/scratch/cnt0024/hmg2840/albert7a/anaconda3/lib/python3.7/site-packages/tornado/gen.py", line 742, in run
    yielded = self.gen.send(value)
  File "/scratch/cnt0024/hmg2840/albert7a/anaconda3/lib/python3.7/site-packages/distributed/nanny.py", line 303, in instantiate
    timedelta(seconds=self.death_timeout), self.process.start()
  File "/scratch/cnt0024/hmg2840/albert7a/anaconda3/lib/python3.7/site-packages/tornado/gen.py", line 729, in run
    value = future.result()
tornado.util.TimeoutError: Timeout
tornado.application - ERROR - Multiple exceptions in yield list
Traceback (most recent call last):
  File "/scratch/cnt0024/hmg2840/albert7a/anaconda3/lib/python3.7/site-packages/tornado/gen.py", line 501, in callback
    result_list.append(f.result())
  File "/scratch/cnt0024/hmg2840/albert7a/anaconda3/lib/python3.7/asyncio/tasks.py", line 603, in _wrap_awaitable
    return (yield from awaitable.__await__())
  File "/scratch/cnt0024/hmg2840/albert7a/anaconda3/lib/python3.7/site-packages/tornado/gen.py", line 736, in run
    yielded = self.gen.throw(*exc_info)  # type: ignore
  File "/scratch/cnt0024/hmg2840/albert7a/anaconda3/lib/python3.7/site-packages/distributed/nanny.py", line 224, in _start
    response = yield self.instantiate()
  File "/scratch/cnt0024/hmg2840/albert7a/anaconda3/lib/python3.7/site-packages/tornado/gen.py", line 729, in run
    value = future.result()
  File "/scratch/cnt0024/hmg2840/albert7a/anaconda3/lib/python3.7/site-packages/tornado/gen.py", line 742, in run
    yielded = self.gen.send(value)
  File "/scratch/cnt0024/hmg2840/albert7a/anaconda3/lib/python3.7/site-packages/distributed/nanny.py", line 303, in instantiate
    timedelta(seconds=self.death_timeout), self.process.start()
  File "/scratch/cnt0024/hmg2840/albert7a/anaconda3/lib/python3.7/site-packages/tornado/gen.py", line 729, in run
    value = future.result()
tornado.util.TimeoutError: Timeout
distributed.dask_worker - INFO - End worker
Traceback (most recent call last):
  File "/scratch/cnt0024/hmg2840/albert7a/anaconda3/lib/python3.7/runpy.py", line 193, in _run_module_as_main
    "__main__", mod_spec)
  File "/scratch/cnt0024/hmg2840/albert7a/anaconda3/lib/python3.7/runpy.py", line 85, in _run_code
    exec(code, run_globals)
  File "/scratch/cnt0024/hmg2840/albert7a/anaconda3/lib/python3.7/site-packages/distributed/cli/dask_worker.py", line 405, in <module>
    go()
  File "/scratch/cnt0024/hmg2840/albert7a/anaconda3/lib/python3.7/site-packages/distributed/cli/dask_worker.py", line 401, in go
    main()
  File "/scratch/cnt0024/hmg2840/albert7a/anaconda3/lib/python3.7/site-packages/click/core.py", line 764, in __call__
    return self.main(*args, **kwargs)
  File "/scratch/cnt0024/hmg2840/albert7a/anaconda3/lib/python3.7/site-packages/click/core.py", line 717, in main
    rv = self.invoke(ctx)
  File "/scratch/cnt0024/hmg2840/albert7a/anaconda3/lib/python3.7/site-packages/click/core.py", line 956, in invoke
    return ctx.invoke(self.callback, **ctx.params)
  File "/scratch/cnt0024/hmg2840/albert7a/anaconda3/lib/python3.7/site-packages/click/core.py", line 555, in invoke
    return callback(*args, **kwargs)
  File "/scratch/cnt0024/hmg2840/albert7a/anaconda3/lib/python3.7/site-packages/distributed/cli/dask_worker.py", line 392, in main
    raise TimeoutError("Timed out starting worker.") from None
tornado.util.TimeoutError: Timed out starting worker.
/scratch/cnt0024/hmg2840/albert7a/anaconda3/lib/python3.7/site-packages/distributed/utils.py:136: RuntimeWarning: Couldn't detect a suitable IP address for reaching '8.8.8.8', defaulting to '127.0.0.1': [Errno 101] Network is unreachable
  RuntimeWarning,
